return { { ["y"] = 2, ["x"] = 0, ["name"] = "default:sign_wall", ["z"] = 9, ["meta"] = { ["inventory"] = {  }, ["fields"] = { ["text"] = "Clock", ["infotext"] = "\"Clock\"", ["formspec"] = "field[text;;${text}]" } }, ["param2"] = 2, ["param1"] = 159 }, { ["y"] = 0, ["x"] = 1, ["name"] = "default:steelblock", ["z"] = 0, ["meta"] = { ["inventory"] = {  }, ["fields"] = {  } }, ["param2"] = 0, ["param1"] = 0 }, { ["y"] = 0, ["x"] = 1, ["name"] = "mesecons_lightstone:lightstone_green_on", ["z"] = 1, ["meta"] = { ["inventory"] = {  }, ["fields"] = {  } }, ["param2"] = 0, ["param1"] = 0 }, { ["y"] = 0, ["x"] = 1, ["name"] = "mesecons_lightstone:lightstone_green_on", ["z"] = 2, ["meta"] = { ["inventory"] = {  }, ["fields"] = {  } }, ["param2"] = 0, ["param1"] = 0 }, { ["y"] = 0, ["x"] = 1, ["name"] = "mesecons_lightstone:lightstone_green_on", ["z"] = 3, ["meta"] = { ["inventory"] = {  }, ["fields"] = {  } }, ["param2"] = 0, ["param1"] = 0 }, { ["y"] = 0, ["x"] = 1, ["name"] = "default:steelblock", ["z"] = 4, ["meta"] = { ["inventory"] = {  }, ["fields"] = {  } }, ["param2"] = 0, ["param1"] = 0 }, { ["y"] = 0, ["x"] = 1, ["name"] = "mesecons_lightstone:lightstone_green_on", ["z"] = 5, ["meta"] = { ["inventory"] = {  }, ["fields"] = {  } }, ["param2"] = 0, ["param1"] = 0 }, { ["y"] = 0, ["x"] = 1, ["name"] = "mesecons_lightstone:lightstone_green_on", ["z"] = 6, ["meta"] = { ["inventory"] = {  }, ["fields"] = {  } }, ["param2"] = 0, ["param1"] = 0 }, { ["y"] = 0, ["x"] = 1, ["name"] = "mesecons_lightstone:lightstone_green_on", ["z"] = 7, ["meta"] = { ["inventory"] = {  }, ["fields"] = {  } }, ["param2"] = 0, ["param1"] = 0 }, { ["y"] = 0, ["x"] = 1, ["name"] = "default:steelblock", ["z"] = 8, ["meta"] = { ["inventory"] = {  }, ["fields"] = {  } }, ["param2"] = 0, ["param1"] = 0 }, { ["y"] = 0, ["x"] = 1, ["name"] = "default:steelblock", ["z"] = 9, ["meta"] = { ["inventory"] = {  }, ["fields"] = {  } }, ["param2"] = 0, ["param1"] = 0 }, { ["y"] = 0, ["x"] = 1, ["name"] = "default:steelblock", ["z"] = 10, ["meta"] = { ["inventory"] = {  }, ["fields"] = {  } }, ["param2"] = 0, ["param1"] = 0 }, { ["y"] = 0, ["x"] = 1, ["name"] = "mesecons_lightstone:lightstone_green_on", ["z"] = 11, ["meta"] = { ["inventory"] = {  }, ["fields"] = {  } }, ["param2"] = 0, ["param1"] = 0 }, { ["y"] = 0, ["x"] = 1, ["name"] = "mesecons_lightstone:lightstone_green_on", ["z"] = 12, ["meta"] = { ["inventory"] = {  }, ["fields"] = {  } }, ["param2"] = 0, ["param1"] = 0 }, { ["y"] = 0, ["x"] = 1, ["name"] = "mesecons_lightstone:lightstone_green_on", ["z"] = 13, ["meta"] = { ["inventory"] = {  }, ["fields"] = {  } }, ["param2"] = 0, ["param1"] = 0 }, { ["y"] = 0, ["x"] = 1, ["name"] = "default:steelblock", ["z"] = 14, ["meta"] = { ["inventory"] = {  }, ["fields"] = {  } }, ["param2"] = 0, ["param1"] = 0 }, { ["y"] = 0, ["x"] = 1, ["name"] = "mesecons_lightstone:lightstone_green_on", ["z"] = 15, ["meta"] = { ["inventory"] = {  }, ["fields"] = {  } }, ["param2"] = 0, ["param1"] = 0 }, { ["y"] = 0, ["x"] = 1, ["name"] = "mesecons_lightstone:lightstone_green_on", ["z"] = 16, ["meta"] = { ["inventory"] = {  }, ["fields"] = {  } }, ["param2"] = 0, ["param1"] = 0 }, { ["y"] = 0, ["x"] = 1, ["name"] = "mesecons_lightstone:lightstone_green_on", ["z"] = 17, ["meta"] = { ["inventory"] = {  }, ["fields"] = {  } }, ["param2"] = 0, ["param1"] = 0 }, { ["y"] = 0, ["x"] = 1, ["name"] = "default:steelblock", ["z"] = 18, ["meta"] = { ["inventory"] = {  }, ["fields"] = {  } }, ["param2"] = 0, ["param1"] = 0 }, { ["y"] = 1, ["x"] = 1, ["name"] = "default:steelblock", ["z"] = 0, ["meta"] = { ["inventory"] = {  }, ["fields"] = {  } }, ["param2"] = 0, ["param1"] = 0 }, { ["y"] = 1, ["x"] = 1, ["name"] = "mesecons_lightstone:lightstone_green_on", ["z"] = 1, ["meta"] = { ["inventory"] = {  }, ["fields"] = {  } }, ["param2"] = 0, ["param1"] = 0 }, { ["y"] = 1, ["x"] = 1, ["name"] = "mesecons_lightstone:lightstone_green_off", ["z"] = 2, ["meta"] = { ["inventory"] = {  }, ["fields"] = {  } }, ["param2"] = 0, ["param1"] = 0 }, { ["y"] = 1, ["x"] = 1, ["name"] = "mesecons_lightstone:lightstone_green_off", ["z"] = 3, ["meta"] = { ["inventory"] = {  }, ["fields"] = {  } }, ["param2"] = 0, ["param1"] = 0 }, { ["y"] = 1, ["x"] = 1, ["name"] = "default:steelblock", ["z"] = 4, ["meta"] = { ["inventory"] = {  }, ["fields"] = {  } }, ["param2"] = 0, ["param1"] = 0 }, { ["y"] = 1, ["x"] = 1, ["name"] = "mesecons_lightstone:lightstone_green_on", ["z"] = 5, ["meta"] = { ["inventory"] = {  }, ["fields"] = {  } }, ["param2"] = 0, ["param1"] = 0 }, { ["y"] = 1, ["x"] = 1, ["name"] = "mesecons_lightstone:lightstone_green_off", ["z"] = 6, ["meta"] = { ["inventory"] = {  }, ["fields"] = {  } }, ["param2"] = 0, ["param1"] = 0 }, { ["y"] = 1, ["x"] = 1, ["name"] = "mesecons_lightstone:lightstone_green_off", ["z"] = 7, ["meta"] = { ["inventory"] = {  }, ["fields"] = {  } }, ["param2"] = 0, ["param1"] = 0 }, { ["y"] = 1, ["x"] = 1, ["name"] = "default:steelblock", ["z"] = 8, ["meta"] = { ["inventory"] = {  }, ["fields"] = {  } }, ["param2"] = 0, ["param1"] = 0 }, { ["y"] = 1, ["x"] = 1, ["name"] = "mesecons_lightstone:lightstone_green_off", ["z"] = 9, ["meta"] = { ["inventory"] = {  }, ["fields"] = {  } }, ["param2"] = 0, ["param1"] = 0 }, { ["y"] = 1, ["x"] = 1, ["name"] = "default:steelblock", ["z"] = 10, ["meta"] = { ["inventory"] = {  }, ["fields"] = {  } }, ["param2"] = 0, ["param1"] = 0 }, { ["y"] = 1, ["x"] = 1, ["name"] = "mesecons_lightstone:lightstone_green_on", ["z"] = 11, ["meta"] = { ["inventory"] = {  }, ["fields"] = {  } }, ["param2"] = 0, ["param1"] = 0 }, { ["y"] = 1, ["x"] = 1, ["name"] = "mesecons_lightstone:lightstone_green_off", ["z"] = 12, ["meta"] = { ["inventory"] = {  }, ["fields"] = {  } }, ["param2"] = 0, ["param1"] = 0 }, { ["y"] = 1, ["x"] = 1, ["name"] = "mesecons_lightstone:lightstone_green_on", ["z"] = 13, ["meta"] = { ["inventory"] = {  }, ["fields"] = {  } }, ["param2"] = 0, ["param1"] = 0 }, { ["y"] = 1, ["x"] = 1, ["name"] = "default:steelblock", ["z"] = 14, ["meta"] = { ["inventory"] = {  }, ["fields"] = {  } }, ["param2"] = 0, ["param1"] = 0 }, { ["y"] = 1, ["x"] = 1, ["name"] = "mesecons_lightstone:lightstone_green_on", ["z"] = 15, ["meta"] = { ["inventory"] = {  }, ["fields"] = {  } }, ["param2"] = 0, ["param1"] = 0 }, { ["y"] = 1, ["x"] = 1, ["name"] = "mesecons_lightstone:lightstone_green_off", ["z"] = 16, ["meta"] = { ["inventory"] = {  }, ["fields"] = {  } }, ["param2"] = 0, ["param1"] = 0 }, { ["y"] = 1, ["x"] = 1, ["name"] = "mesecons_lightstone:lightstone_green_on", ["z"] = 17, ["meta"] = { ["inventory"] = {  }, ["fields"] = {  } }, ["param2"] = 0, ["param1"] = 0 }, { ["y"] = 1, ["x"] = 1, ["name"] = "default:steelblock", ["z"] = 18, ["meta"] = { ["inventory"] = {  }, ["fields"] = {  } }, ["param2"] = 0, ["param1"] = 0 }, { ["y"] = 2, ["x"] = 1, ["name"] = "default:steelblock", ["z"] = 0, ["meta"] = { ["inventory"] = {  }, ["fields"] = {  } }, ["param2"] = 0, ["param1"] = 0 }, { ["y"] = 2, ["x"] = 1, ["name"] = "mesecons_lightstone:lightstone_green_on", ["z"] = 1, ["meta"] = { ["inventory"] = {  }, ["fields"] = {  } }, ["param2"] = 0, ["param1"] = 0 }, { ["y"] = 2, ["x"] = 1, ["name"] = "mesecons_lightstone:lightstone_green_on", ["z"] = 2, ["meta"] = { ["inventory"] = {  }, ["fields"] = {  } }, ["param2"] = 0, ["param1"] = 0 }, { ["y"] = 2, ["x"] = 1, ["name"] = "mesecons_lightstone:lightstone_green_on", ["z"] = 3, ["meta"] = { ["inventory"] = {  }, ["fields"] = {  } }, ["param2"] = 0, ["param1"] = 0 }, { ["y"] = 2, ["x"] = 1, ["name"] = "default:steelblock", ["z"] = 4, ["meta"] = { ["inventory"] = {  }, ["fields"] = {  } }, ["param2"] = 0, ["param1"] = 0 }, { ["y"] = 2, ["x"] = 1, ["name"] = "mesecons_lightstone:lightstone_green_on", ["z"] = 5, ["meta"] = { ["inventory"] = {  }, ["fields"] = {  } }, ["param2"] = 0, ["param1"] = 0 }, { ["y"] = 2, ["x"] = 1, ["name"] = "mesecons_lightstone:lightstone_green_on", ["z"] = 6, ["meta"] = { ["inventory"] = {  }, ["fields"] = {  } }, ["param2"] = 0, ["param1"] = 0 }, { ["y"] = 2, ["x"] = 1, ["name"] = "mesecons_lightstone:lightstone_green_on", ["z"] = 7, ["meta"] = { ["inventory"] = {  }, ["fields"] = {  } }, ["param2"] = 0, ["param1"] = 0 }, { ["y"] = 2, ["x"] = 1, ["name"] = "default:steelblock", ["z"] = 8, ["meta"] = { ["inventory"] = {  }, ["fields"] = {  } }, ["param2"] = 0, ["param1"] = 0 }, { ["y"] = 2, ["x"] = 1, ["name"] = "default:steelblock", ["z"] = 9, ["meta"] = { ["inventory"] = {  }, ["fields"] = {  } }, ["param2"] = 0, ["param1"] = 0 }, { ["y"] = 2, ["x"] = 1, ["name"] = "default:steelblock", ["z"] = 10, ["meta"] = { ["inventory"] = {  }, ["fields"] = {  } }, ["param2"] = 0, ["param1"] = 0 }, { ["y"] = 2, ["x"] = 1, ["name"] = "mesecons_lightstone:lightstone_green_on", ["z"] = 11, ["meta"] = { ["inventory"] = {  }, ["fields"] = {  } }, ["param2"] = 0, ["param1"] = 0 }, { ["y"] = 2, ["x"] = 1, ["name"] = "mesecons_lightstone:lightstone_green_on", ["z"] = 12, ["meta"] = { ["inventory"] = {  }, ["fields"] = {  } }, ["param2"] = 0, ["param1"] = 0 }, { ["y"] = 2, ["x"] = 1, ["name"] = "mesecons_lightstone:lightstone_green_on", ["z"] = 13, ["meta"] = { ["inventory"] = {  }, ["fields"] = {  } }, ["param2"] = 0, ["param1"] = 0 }, { ["y"] = 2, ["x"] = 1, ["name"] = "default:steelblock", ["z"] = 14, ["meta"] = { ["inventory"] = {  }, ["fields"] = {  } }, ["param2"] = 0, ["param1"] = 0 }, { ["y"] = 2, ["x"] = 1, ["name"] = "mesecons_lightstone:lightstone_green_on", ["z"] = 15, ["meta"] = { ["inventory"] = {  }, ["fields"] = {  } }, ["param2"] = 0, ["param1"] = 0 }, { ["y"] = 2, ["x"] = 1, ["name"] = "mesecons_lightstone:lightstone_green_off", ["z"] = 16, ["meta"] = { ["inventory"] = {  }, ["fields"] = {  } }, ["param2"] = 0, ["param1"] = 0 }, { ["y"] = 2, ["x"] = 1, ["name"] = "mesecons_lightstone:lightstone_green_on", ["z"] = 17, ["meta"] = { ["inventory"] = {  }, ["fields"] = {  } }, ["param2"] = 0, ["param1"] = 0 }, { ["y"] = 2, ["x"] = 1, ["name"] = "default:steelblock", ["z"] = 18, ["meta"] = { ["inventory"] = {  }, ["fields"] = {  } }, ["param2"] = 0, ["param1"] = 0 }, { ["y"] = 3, ["x"] = 1, ["name"] = "default:steelblock", ["z"] = 0, ["meta"] = { ["inventory"] = {  }, ["fields"] = {  } }, ["param2"] = 0, ["param1"] = 0 }, { ["y"] = 3, ["x"] = 1, ["name"] = "mesecons_lightstone:lightstone_green_on", ["z"] = 1, ["meta"] = { ["inventory"] = {  }, ["fields"] = {  } }, ["param2"] = 0, ["param1"] = 0 }, { ["y"] = 3, ["x"] = 1, ["name"] = "mesecons_lightstone:lightstone_green_off", ["z"] = 2, ["meta"] = { ["inventory"] = {  }, ["fields"] = {  } }, ["param2"] = 0, ["param1"] = 0 }, { ["y"] = 3, ["x"] = 1, ["name"] = "mesecons_lightstone:lightstone_green_on", ["z"] = 3, ["meta"] = { ["inventory"] = {  }, ["fields"] = {  } }, ["param2"] = 0, ["param1"] = 0 }, { ["y"] = 3, ["x"] = 1, ["name"] = "default:steelblock", ["z"] = 4, ["meta"] = { ["inventory"] = {  }, ["fields"] = {  } }, ["param2"] = 0, ["param1"] = 0 }, { ["y"] = 3, ["x"] = 1, ["name"] = "mesecons_lightstone:lightstone_green_off", ["z"] = 5, ["meta"] = { ["inventory"] = {  }, ["fields"] = {  } }, ["param2"] = 0, ["param1"] = 0 }, { ["y"] = 3, ["x"] = 1, ["name"] = "mesecons_lightstone:lightstone_green_off", ["z"] = 6, ["meta"] = { ["inventory"] = {  }, ["fields"] = {  } }, ["param2"] = 0, ["param1"] = 0 }, { ["y"] = 3, ["x"] = 1, ["name"] = "mesecons_lightstone:lightstone_green_on", ["z"] = 7, ["meta"] = { ["inventory"] = {  }, ["fields"] = {  } }, ["param2"] = 0, ["param1"] = 0 }, { ["y"] = 3, ["x"] = 1, ["name"] = "default:steelblock", ["z"] = 8, ["meta"] = { ["inventory"] = {  }, ["fields"] = {  } }, ["param2"] = 0, ["param1"] = 0 }, { ["y"] = 3, ["x"] = 1, ["name"] = "mesecons_lightstone:lightstone_green_off", ["z"] = 9, ["meta"] = { ["inventory"] = {  }, ["fields"] = {  } }, ["param2"] = 0, ["param1"] = 0 }, { ["y"] = 3, ["x"] = 1, ["name"] = "default:steelblock", ["z"] = 10, ["meta"] = { ["inventory"] = {  }, ["fields"] = {  } }, ["param2"] = 0, ["param1"] = 0 }, { ["y"] = 3, ["x"] = 1, ["name"] = "mesecons_lightstone:lightstone_green_off", ["z"] = 11, ["meta"] = { ["inventory"] = {  }, ["fields"] = {  } }, ["param2"] = 0, ["param1"] = 0 }, { ["y"] = 3, ["x"] = 1, ["name"] = "mesecons_lightstone:lightstone_green_off", ["z"] = 12, ["meta"] = { ["inventory"] = {  }, ["fields"] = {  } }, ["param2"] = 0, ["param1"] = 0 }, { ["y"] = 3, ["x"] = 1, ["name"] = "mesecons_lightstone:lightstone_green_on", ["z"] = 13, ["meta"] = { ["inventory"] = {  }, ["fields"] = {  } }, ["param2"] = 0, ["param1"] = 0 }, { ["y"] = 3, ["x"] = 1, ["name"] = "default:steelblock", ["z"] = 14, ["meta"] = { ["inventory"] = {  }, ["fields"] = {  } }, ["param2"] = 0, ["param1"] = 0 }, { ["y"] = 3, ["x"] = 1, ["name"] = "mesecons_lightstone:lightstone_green_on", ["z"] = 15, ["meta"] = { ["inventory"] = {  }, ["fields"] = {  } }, ["param2"] = 0, ["param1"] = 0 }, { ["y"] = 3, ["x"] = 1, ["name"] = "mesecons_lightstone:lightstone_green_off", ["z"] = 16, ["meta"] = { ["inventory"] = {  }, ["fields"] = {  } }, ["param2"] = 0, ["param1"] = 0 }, { ["y"] = 3, ["x"] = 1, ["name"] = "mesecons_lightstone:lightstone_green_on", ["z"] = 17, ["meta"] = { ["inventory"] = {  }, ["fields"] = {  } }, ["param2"] = 0, ["param1"] = 0 }, { ["y"] = 3, ["x"] = 1, ["name"] = "default:steelblock", ["z"] = 18, ["meta"] = { ["inventory"] = {  }, ["fields"] = {  } }, ["param2"] = 0, ["param1"] = 0 }, { ["y"] = 4, ["x"] = 1, ["name"] = "default:steelblock", ["z"] = 0, ["meta"] = { ["inventory"] = {  }, ["fields"] = {  } }, ["param2"] = 0, ["param1"] = 0 }, { ["y"] = 4, ["x"] = 1, ["name"] = "mesecons_lightstone:lightstone_green_on", ["z"] = 1, ["meta"] = { ["inventory"] = {  }, ["fields"] = {  } }, ["param2"] = 0, ["param1"] = 0 }, { ["y"] = 4, ["x"] = 1, ["name"] = "mesecons_lightstone:lightstone_green_on", ["z"] = 2, ["meta"] = { ["inventory"] = {  }, ["fields"] = {  } }, ["param2"] = 0, ["param1"] = 0 }, { ["y"] = 4, ["x"] = 1, ["name"] = "mesecons_lightstone:lightstone_green_on", ["z"] = 3, ["meta"] = { ["inventory"] = {  }, ["fields"] = {  } }, ["param2"] = 0, ["param1"] = 0 }, { ["y"] = 4, ["x"] = 1, ["name"] = "default:steelblock", ["z"] = 4, ["meta"] = { ["inventory"] = {  }, ["fields"] = {  } }, ["param2"] = 0, ["param1"] = 0 }, { ["y"] = 4, ["x"] = 1, ["name"] = "mesecons_lightstone:lightstone_green_on", ["z"] = 5, ["meta"] = { ["inventory"] = {  }, ["fields"] = {  } }, ["param2"] = 0, ["param1"] = 0 }, { ["y"] = 4, ["x"] = 1, ["name"] = "mesecons_lightstone:lightstone_green_on", ["z"] = 6, ["meta"] = { ["inventory"] = {  }, ["fields"] = {  } }, ["param2"] = 0, ["param1"] = 0 }, { ["y"] = 4, ["x"] = 1, ["name"] = "mesecons_lightstone:lightstone_green_on", ["z"] = 7, ["meta"] = { ["inventory"] = {  }, ["fields"] = {  } }, ["param2"] = 0, ["param1"] = 0 }, { ["y"] = 4, ["x"] = 1, ["name"] = "default:steelblock", ["z"] = 8, ["meta"] = { ["inventory"] = {  }, ["fields"] = {  } }, ["param2"] = 0, ["param1"] = 0 }, { ["y"] = 4, ["x"] = 1, ["name"] = "default:steelblock", ["z"] = 9, ["meta"] = { ["inventory"] = {  }, ["fields"] = {  } }, ["param2"] = 0, ["param1"] = 0 }, { ["y"] = 4, ["x"] = 1, ["name"] = "default:steelblock", ["z"] = 10, ["meta"] = { ["inventory"] = {  }, ["fields"] = {  } }, ["param2"] = 0, ["param1"] = 0 }, { ["y"] = 4, ["x"] = 1, ["name"] = "mesecons_lightstone:lightstone_green_on", ["z"] = 11, ["meta"] = { ["inventory"] = {  }, ["fields"] = {  } }, ["param2"] = 0, ["param1"] = 0 }, { ["y"] = 4, ["x"] = 1, ["name"] = "mesecons_lightstone:lightstone_green_on", ["z"] = 12, ["meta"] = { ["inventory"] = {  }, ["fields"] = {  } }, ["param2"] = 0, ["param1"] = 0 }, { ["y"] = 4, ["x"] = 1, ["name"] = "mesecons_lightstone:lightstone_green_on", ["z"] = 13, ["meta"] = { ["inventory"] = {  }, ["fields"] = {  } }, ["param2"] = 0, ["param1"] = 0 }, { ["y"] = 4, ["x"] = 1, ["name"] = "default:steelblock", ["z"] = 14, ["meta"] = { ["inventory"] = {  }, ["fields"] = {  } }, ["param2"] = 0, ["param1"] = 0 }, { ["y"] = 4, ["x"] = 1, ["name"] = "mesecons_lightstone:lightstone_green_on", ["z"] = 15, ["meta"] = { ["inventory"] = {  }, ["fields"] = {  } }, ["param2"] = 0, ["param1"] = 0 }, { ["y"] = 4, ["x"] = 1, ["name"] = "mesecons_lightstone:lightstone_green_on", ["z"] = 16, ["meta"] = { ["inventory"] = {  }, ["fields"] = {  } }, ["param2"] = 0, ["param1"] = 0 }, { ["y"] = 4, ["x"] = 1, ["name"] = "mesecons_lightstone:lightstone_green_on", ["z"] = 17, ["meta"] = { ["inventory"] = {  }, ["fields"] = {  } }, ["param2"] = 0, ["param1"] = 0 }, { ["y"] = 4, ["x"] = 1, ["name"] = "default:steelblock", ["z"] = 18, ["meta"] = { ["inventory"] = {  }, ["fields"] = {  } }, ["param2"] = 0, ["param1"] = 0 }, { ["y"] = 5, ["x"] = 1, ["name"] = "default:steelblock", ["z"] = 0, ["meta"] = { ["inventory"] = {  }, ["fields"] = {  } }, ["param2"] = 0, ["param1"] = 0 }, { ["y"] = 5, ["x"] = 1, ["name"] = "default:steelblock", ["z"] = 1, ["meta"] = { ["inventory"] = {  }, ["fields"] = {  } }, ["param2"] = 0, ["param1"] = 0 }, { ["y"] = 5, ["x"] = 1, ["name"] = "default:steelblock", ["z"] = 2, ["meta"] = { ["inventory"] = {  }, ["fields"] = {  } }, ["param2"] = 0, ["param1"] = 0 }, { ["y"] = 5, ["x"] = 1, ["name"] = "default:steelblock", ["z"] = 3, ["meta"] = { ["inventory"] = {  }, ["fields"] = {  } }, ["param2"] = 0, ["param1"] = 0 }, { ["y"] = 5, ["x"] = 1, ["name"] = "default:steelblock", ["z"] = 4, ["meta"] = { ["inventory"] = {  }, ["fields"] = {  } }, ["param2"] = 0, ["param1"] = 0 }, { ["y"] = 5, ["x"] = 1, ["name"] = "default:steelblock", ["z"] = 5, ["meta"] = { ["inventory"] = {  }, ["fields"] = {  } }, ["param2"] = 0, ["param1"] = 0 }, { ["y"] = 5, ["x"] = 1, ["name"] = "default:steelblock", ["z"] = 6, ["meta"] = { ["inventory"] = {  }, ["fields"] = {  } }, ["param2"] = 0, ["param1"] = 0 }, { ["y"] = 5, ["x"] = 1, ["name"] = "default:steelblock", ["z"] = 7, ["meta"] = { ["inventory"] = {  }, ["fields"] = {  } }, ["param2"] = 0, ["param1"] = 0 }, { ["y"] = 5, ["x"] = 1, ["name"] = "default:steelblock", ["z"] = 8, ["meta"] = { ["inventory"] = {  }, ["fields"] = {  } }, ["param2"] = 0, ["param1"] = 0 }, { ["y"] = 5, ["x"] = 1, ["name"] = "default:steelblock", ["z"] = 9, ["meta"] = { ["inventory"] = {  }, ["fields"] = {  } }, ["param2"] = 0, ["param1"] = 0 }, { ["y"] = 5, ["x"] = 1, ["name"] = "default:steelblock", ["z"] = 10, ["meta"] = { ["inventory"] = {  }, ["fields"] = {  } }, ["param2"] = 0, ["param1"] = 0 }, { ["y"] = 5, ["x"] = 1, ["name"] = "default:steelblock", ["z"] = 11, ["meta"] = { ["inventory"] = {  }, ["fields"] = {  } }, ["param2"] = 0, ["param1"] = 0 }, { ["y"] = 5, ["x"] = 1, ["name"] = "default:steelblock", ["z"] = 12, ["meta"] = { ["inventory"] = {  }, ["fields"] = {  } }, ["param2"] = 0, ["param1"] = 0 }, { ["y"] = 5, ["x"] = 1, ["name"] = "default:steelblock", ["z"] = 13, ["meta"] = { ["inventory"] = {  }, ["fields"] = {  } }, ["param2"] = 0, ["param1"] = 0 }, { ["y"] = 5, ["x"] = 1, ["name"] = "default:steelblock", ["z"] = 14, ["meta"] = { ["inventory"] = {  }, ["fields"] = {  } }, ["param2"] = 0, ["param1"] = 0 }, { ["y"] = 5, ["x"] = 1, ["name"] = "default:steelblock", ["z"] = 15, ["meta"] = { ["inventory"] = {  }, ["fields"] = {  } }, ["param2"] = 0, ["param1"] = 0 }, { ["y"] = 5, ["x"] = 1, ["name"] = "default:steelblock", ["z"] = 16, ["meta"] = { ["inventory"] = {  }, ["fields"] = {  } }, ["param2"] = 0, ["param1"] = 0 }, { ["y"] = 5, ["x"] = 1, ["name"] = "default:steelblock", ["z"] = 17, ["meta"] = { ["inventory"] = {  }, ["fields"] = {  } }, ["param2"] = 0, ["param1"] = 0 }, { ["y"] = 5, ["x"] = 1, ["name"] = "default:steelblock", ["z"] = 18, ["meta"] = { ["inventory"] = {  }, ["fields"] = {  } }, ["param2"] = 0, ["param1"] = 0 }, { ["y"] = 0, ["x"] = 2, ["name"] = "default:steelblock", ["z"] = 0, ["meta"] = { ["inventory"] = {  }, ["fields"] = {  } }, ["param2"] = 0, ["param1"] = 0 }, { ["y"] = 0, ["x"] = 2, ["name"] = "mesecons_extrawires:corner_on", ["z"] = 1, ["meta"] = { ["inventory"] = {  }, ["fields"] = {  } }, ["param2"] = 1, ["param1"] = 187 }, { ["y"] = 0, ["x"] = 2, ["name"] = "mesecons_luacontroller:luacontroller1011", ["z"] = 2, ["meta"] = { ["inventory"] = {  }, ["fields"] = { ["lc_memory"] = "return { [\"accept\"] = { [0] = true, [2] = true, [8] = true, [3] = true, [6] = true, [5] = true, [9] = true } }", ["heat"] = "1", ["formspec"] = "size[10,8]background[-0.2,-0.25;10.4,8.75;jeija_luac_background.png]textarea[0.2,0.6;10.2,5;code;;if event.type == \"program\" then\r  mem.accept = {\\[0\\]=true, \\[2\\]=true, \\[3\\]=true, \\[5\\]=true, \\[6\\]=true, \\[8\\]=true, \\[9\\]=true}\relseif event.type == \"digiline\" then\r  port.a = mem.accept\\[event.msg.minute\\]\r  port.b, port.d = port.a, port.a\rend]image_button[3.75,6;2.5,1;jeija_luac_runbutton.png;program;]image_button_exit[9.72,-0.25;0.425,0.4;jeija_close_window.png;exit;]label[0.1,5;]", ["code"] = "if event.type == \"program\" then\r  mem.accept = {[0]=true, [2]=true, [3]=true, [5]=true, [6]=true, [8]=true, [9]=true}\relseif event.type == \"digiline\" then\r  port.a = mem.accept[event.msg.minute]\r  port.b, port.d = port.a, port.a\rend" } }, ["param2"] = 0, ["param1"] = 187 }, { ["y"] = 0, ["x"] = 2, ["name"] = "mesecons_extrawires:corner_on", ["z"] = 3, ["meta"] = { ["inventory"] = {  }, ["fields"] = {  } }, ["param2"] = 0, ["param1"] = 187 }, { ["y"] = 0, ["x"] = 2, ["name"] = "default:glass", ["z"] = 4, ["meta"] = { ["inventory"] = {  }, ["fields"] = {  } }, ["param2"] = 0, ["param1"] = 170 }, { ["y"] = 0, ["x"] = 2, ["name"] = "mesecons_extrawires:corner_on", ["z"] = 5, ["meta"] = { ["inventory"] = {  }, ["fields"] = {  } }, ["param2"] = 1, ["param1"] = 187 }, { ["y"] = 0, ["x"] = 2, ["name"] = "mesecons_luacontroller:luacontroller1011", ["z"] = 6, ["meta"] = { ["inventory"] = {  }, ["fields"] = { ["lc_memory"] = "return { [\"accept\"] = { [0] = true, [2] = true, [8] = true, [3] = true, [6] = true, [5] = true, [9] = true } }", ["heat"] = "2", ["formspec"] = "size[10,8]background[-0.2,-0.25;10.4,8.75;jeija_luac_background.png]textarea[0.2,0.6;10.2,5;code;;if event.type == \"program\" then\r  mem.accept = {\\[0\\]=true, \\[2\\]=true, \\[3\\]=true, \\[5\\]=true, \\[6\\]=true, \\[8\\]=true, \\[9\\]=true}\relseif event.type == \"digiline\" then\r  port.a = mem.accept\\[event.msg.tenminute\\]\r  port.b, port.d = port.a, port.a\rend]image_button[3.75,6;2.5,1;jeija_luac_runbutton.png;program;]image_button_exit[9.72,-0.25;0.425,0.4;jeija_close_window.png;exit;]label[0.1,5;]", ["code"] = "if event.type == \"program\" then\r  mem.accept = {[0]=true, [2]=true, [3]=true, [5]=true, [6]=true, [8]=true, [9]=true}\relseif event.type == \"digiline\" then\r  port.a = mem.accept[event.msg.tenminute]\r  port.b, port.d = port.a, port.a\rend" } }, ["param2"] = 0, ["param1"] = 187 }, { ["y"] = 0, ["x"] = 2, ["name"] = "mesecons_extrawires:corner_on", ["z"] = 7, ["meta"] = { ["inventory"] = {  }, ["fields"] = {  } }, ["param2"] = 0, ["param1"] = 187 }, { ["y"] = 0, ["x"] = 2, ["name"] = "default:glass", ["z"] = 8, ["meta"] = { ["inventory"] = {  }, ["fields"] = {  } }, ["param2"] = 0, ["param1"] = 170 }, { ["y"] = 0, ["x"] = 2, ["name"] = "default:glass", ["z"] = 9, ["meta"] = { ["inventory"] = {  }, ["fields"] = {  } }, ["param2"] = 0, ["param1"] = 153 }, { ["y"] = 0, ["x"] = 2, ["name"] = "default:glass", ["z"] = 10, ["meta"] = { ["inventory"] = {  }, ["fields"] = {  } }, ["param2"] = 0, ["param1"] = 170 }, { ["y"] = 0, ["x"] = 2, ["name"] = "mesecons_extrawires:corner_on", ["z"] = 11, ["meta"] = { ["inventory"] = {  }, ["fields"] = {  } }, ["param2"] = 1, ["param1"] = 187 }, { ["y"] = 0, ["x"] = 2, ["name"] = "mesecons_luacontroller:luacontroller1011", ["z"] = 12, ["meta"] = { ["inventory"] = {  }, ["fields"] = { ["lc_memory"] = "return { [\"accept\"] = { [0] = true, [2] = true, [8] = true, [3] = true, [6] = true, [5] = true, [9] = true } }", ["heat"] = "3", ["formspec"] = "size[10,8]background[-0.2,-0.25;10.4,8.75;jeija_luac_background.png]textarea[0.2,0.6;10.2,5;code;;if event.type == \"program\" then\
  mem.accept = {\\[0\\]=true, \\[2\\]=true, \\[3\\]=true, \\[5\\]=true, \\[6\\]=true, \\[8\\]=true, \\[9\\]=true}\
elseif event.type == \"digiline\" then\r  port.a = mem.accept\\[event.msg.hour\\]\r  port.b, port.d = port.a, port.a\rend]image_button[3.75,6;2.5,1;jeija_luac_runbutton.png;program;]image_button_exit[9.72,-0.25;0.425,0.4;jeija_close_window.png;exit;]label[0.1,5;]", ["code"] = "if event.type == \"program\" then\
  mem.accept = {[0]=true, [2]=true, [3]=true, [5]=true, [6]=true, [8]=true, [9]=true}\
elseif event.type == \"digiline\" then\r  port.a = mem.accept[event.msg.hour]\r  port.b, port.d = port.a, port.a\rend" } }, ["param2"] = 0, ["param1"] = 187 }, { ["y"] = 0, ["x"] = 2, ["name"] = "mesecons_extrawires:corner_on", ["z"] = 13, ["meta"] = { ["inventory"] = {  }, ["fields"] = {  } }, ["param2"] = 0, ["param1"] = 187 }, { ["y"] = 0, ["x"] = 2, ["name"] = "default:glass", ["z"] = 14, ["meta"] = { ["inventory"] = {  }, ["fields"] = {  } }, ["param2"] = 0, ["param1"] = 170 }, { ["y"] = 0, ["x"] = 2, ["name"] = "mesecons_extrawires:corner_on", ["z"] = 15, ["meta"] = { ["inventory"] = {  }, ["fields"] = {  } }, ["param2"] = 1, ["param1"] = 187 }, { ["y"] = 0, ["x"] = 2, ["name"] = "mesecons_luacontroller:luacontroller1011", ["z"] = 16, ["meta"] = { ["inventory"] = {  }, ["fields"] = { ["lc_memory"] = "return { [\"accept\"] = { [0] = true, [2] = true, [8] = true, [3] = true, [9] = true, [5] = true, [6] = true } }", ["heat"] = "-1", ["formspec"] = "size[10,8]background[-0.2,-0.25;10.4,8.75;jeija_luac_background.png]textarea[0.2,0.6;10.2,5;code;;if event.type == \"program\" then\
  mem.accept = {\\[0\\]=true, \\[2\\]=true, \\[3\\]=true, \\[5\\]=true, \\[6\\]=true, \\[8\\]=true, \\[9\\]=true}\
elseif event.type == \"digiline\" then\r  port.a = mem.accept\\[event.msg.tenhour\\]\r  port.b, port.d = port.a, port.a\rend]image_button[3.75,6;2.5,1;jeija_luac_runbutton.png;program;]image_button_exit[9.72,-0.25;0.425,0.4;jeija_close_window.png;exit;]label[0.1,5;]", ["code"] = "if event.type == \"program\" then\
  mem.accept = {[0]=true, [2]=true, [3]=true, [5]=true, [6]=true, [8]=true, [9]=true}\
elseif event.type == \"digiline\" then\r  port.a = mem.accept[event.msg.tenhour]\r  port.b, port.d = port.a, port.a\rend" } }, ["param2"] = 0, ["param1"] = 187 }, { ["y"] = 0, ["x"] = 2, ["name"] = "mesecons_extrawires:corner_on", ["z"] = 17, ["meta"] = { ["inventory"] = {  }, ["fields"] = {  } }, ["param2"] = 0, ["param1"] = 187 }, { ["y"] = 0, ["x"] = 2, ["name"] = "default:steelblock", ["z"] = 18, ["meta"] = { ["inventory"] = {  }, ["fields"] = {  } }, ["param2"] = 0, ["param1"] = 0 }, { ["y"] = 1, ["x"] = 2, ["name"] = "default:steelblock", ["z"] = 0, ["meta"] = { ["inventory"] = {  }, ["fields"] = {  } }, ["param2"] = 0, ["param1"] = 0 }, { ["y"] = 1, ["x"] = 2, ["name"] = "mesecons:wire_01100010_on", ["z"] = 1, ["meta"] = { ["inventory"] = {  }, ["fields"] = {  } }, ["param2"] = 0, ["param1"] = 187 }, { ["y"] = 1, ["x"] = 2, ["name"] = "mesecons_luacontroller:luacontroller1000", ["z"] = 2, ["meta"] = { ["inventory"] = {  }, ["fields"] = { ["lc_memory"] = "return { [\"accept1\"] = { [0] = true, [2] = true, [6] = true, [8] = true }, [\"accept2\"] = { true, [0] = true, [7] = true, [8] = true, [3] = true, [6] = true, [4] = true, [5] = true, [9] = true } }", ["heat"] = "0", ["formspec"] = "size[10,8]background[-0.2,-0.25;10.4,8.75;jeija_luac_background.png]textarea[0.2,0.6;10.2,5;code;;if event.type == \"program\" then\r  mem.accept1 = {\\[0\\]=true, \\[2\\]=true, \\[6\\]=true, \\[8\\]=true}\r  mem.accept2 = {\\[0\\]=true, \\[1\\]=true, \\[3\\]=true, \\[4\\]=true, \\[5\\]=true, \\[6\\]=true, \\[7\\]=true, \\[8\\]=true, \\[9\\]=true}\relseif event.type == \"digiline\" then\r  port.b = mem.accept1\\[event.msg.minute\\]\r  port.d = mem.accept2\\[event.msg.minute\\]\rend]image_button[3.75,6;2.5,1;jeija_luac_runbutton.png;program;]image_button_exit[9.72,-0.25;0.425,0.4;jeija_close_window.png;exit;]label[0.1,5;]", ["code"] = "if event.type == \"program\" then\r  mem.accept1 = {[0]=true, [2]=true, [6]=true, [8]=true}\r  mem.accept2 = {[0]=true, [1]=true, [3]=true, [4]=true, [5]=true, [6]=true, [7]=true, [8]=true, [9]=true}\relseif event.type == \"digiline\" then\r  port.b = mem.accept1[event.msg.minute]\r  port.d = mem.accept2[event.msg.minute]\rend" } }, ["param2"] = 0, ["param1"] = 170 }, { ["y"] = 1, ["x"] = 2, ["name"] = "mesecons:wire_00110010_off", ["z"] = 3, ["meta"] = { ["inventory"] = {  }, ["fields"] = {  } }, ["param2"] = 0, ["param1"] = 170 }, { ["y"] = 1, ["x"] = 2, ["name"] = "default:glass", ["z"] = 4, ["meta"] = { ["inventory"] = {  }, ["fields"] = {  } }, ["param2"] = 0, ["param1"] = 170 }, { ["y"] = 1, ["x"] = 2, ["name"] = "mesecons:wire_01100010_on", ["z"] = 5, ["meta"] = { ["inventory"] = {  }, ["fields"] = {  } }, ["param2"] = 0, ["param1"] = 187 }, { ["y"] = 1, ["x"] = 2, ["name"] = "mesecons_luacontroller:luacontroller1000", ["z"] = 6, ["meta"] = { ["inventory"] = {  }, ["fields"] = { ["lc_memory"] = "return { [\"accept1\"] = { [0] = true, [2] = true, [6] = true, [8] = true }, [\"accept2\"] = { true, [0] = true, [7] = true, [8] = true, [3] = true, [6] = true, [4] = true, [5] = true, [9] = true } }", ["heat"] = "1", ["formspec"] = "size[10,8]background[-0.2,-0.25;10.4,8.75;jeija_luac_background.png]textarea[0.2,0.6;10.2,5;code;;if event.type == \"program\" then\r  mem.accept1 = {\\[0\\]=true, \\[2\\]=true, \\[6\\]=true, \\[8\\]=true}\r  mem.accept2 = {\\[0\\]=true, \\[1\\]=true, \\[3\\]=true, \\[4\\]=true, \\[5\\]=true, \\[6\\]=true, \\[7\\]=true, \\[8\\]=true, \\[9\\]=true}\relseif event.type == \"digiline\" then\r  port.b = mem.accept1\\[event.msg.tenminute\\]\r  port.d = mem.accept2\\[event.msg.tenminute\\]\rend]image_button[3.75,6;2.5,1;jeija_luac_runbutton.png;program;]image_button_exit[9.72,-0.25;0.425,0.4;jeija_close_window.png;exit;]label[0.1,5;]", ["code"] = "if event.type == \"program\" then\r  mem.accept1 = {[0]=true, [2]=true, [6]=true, [8]=true}\r  mem.accept2 = {[0]=true, [1]=true, [3]=true, [4]=true, [5]=true, [6]=true, [7]=true, [8]=true, [9]=true}\relseif event.type == \"digiline\" then\r  port.b = mem.accept1[event.msg.tenminute]\r  port.d = mem.accept2[event.msg.tenminute]\rend" } }, ["param2"] = 0, ["param1"] = 170 }, { ["y"] = 1, ["x"] = 2, ["name"] = "mesecons:wire_00110010_off", ["z"] = 7, ["meta"] = { ["inventory"] = {  }, ["fields"] = {  } }, ["param2"] = 0, ["param1"] = 170 }, { ["y"] = 1, ["x"] = 2, ["name"] = "default:glass", ["z"] = 8, ["meta"] = { ["inventory"] = {  }, ["fields"] = {  } }, ["param2"] = 0, ["param1"] = 153 }, { ["y"] = 1, ["x"] = 2, ["name"] = "mesecons_luacontroller:luacontroller0000", ["z"] = 9, ["meta"] = { ["inventory"] = {  }, ["fields"] = { ["lc_memory"] = "return {  }", ["heat"] = "1", ["formspec"] = "size[10,8]background[-0.2,-0.25;10.4,8.75;jeija_luac_background.png]textarea[0.2,0.6;10.2,5;code;;if event.channel == \"clock\" then\r  time = event.msg * 24\r  hour = math.floor(time)\
  tenhour, hour = math.floor(hour / 10), hour % 10\r  time = (time % 1) * 60\r  minute = math.floor(time)\
  tenminute, minute = math.floor(minute / 10), minute % 10\r  digiline_send(\"\", {tenhour=tenhour, hour=hour, tenminute=tenminute, minute=minute})\rend]image_button[3.75,6;2.5,1;jeija_luac_runbutton.png;program;]image_button_exit[9.72,-0.25;0.425,0.4;jeija_close_window.png;exit;]label[0.1,5;]", ["code"] = "if event.channel == \"clock\" then\r  time = event.msg * 24\r  hour = math.floor(time)\
  tenhour, hour = math.floor(hour / 10), hour % 10\r  time = (time % 1) * 60\r  minute = math.floor(time)\
  tenminute, minute = math.floor(minute / 10), minute % 10\r  digiline_send(\"\", {tenhour=tenhour, hour=hour, tenminute=tenminute, minute=minute})\rend" } }, ["param2"] = 0, ["param1"] = 153 }, { ["y"] = 1, ["x"] = 2, ["name"] = "default:glass", ["z"] = 10, ["meta"] = { ["inventory"] = {  }, ["fields"] = {  } }, ["param2"] = 0, ["param1"] = 170 }, { ["y"] = 1, ["x"] = 2, ["name"] = "mesecons:wire_01100010_on", ["z"] = 11, ["meta"] = { ["inventory"] = {  }, ["fields"] = {  } }, ["param2"] = 0, ["param1"] = 187 }, { ["y"] = 1, ["x"] = 2, ["name"] = "mesecons_luacontroller:luacontroller1010", ["z"] = 12, ["meta"] = { ["inventory"] = {  }, ["fields"] = { ["lc_memory"] = "return { [\"accept1\"] = { [0] = true, [2] = true, [6] = true, [8] = true }, [\"accept2\"] = { true, [0] = true, [7] = true, [8] = true, [3] = true, [6] = true, [4] = true, [5] = true, [9] = true } }", ["heat"] = "1", ["formspec"] = "size[10,8]background[-0.2,-0.25;10.4,8.75;jeija_luac_background.png]textarea[0.2,0.6;10.2,5;code;;if event.type == \"program\" then\r  mem.accept1 = {\\[0\\]=true, \\[2\\]=true, \\[6\\]=true, \\[8\\]=true}\r  mem.accept2 = {\\[0\\]=true, \\[1\\]=true, \\[3\\]=true, \\[4\\]=true, \\[5\\]=true, \\[6\\]=true, \\[7\\]=true, \\[8\\]=true, \\[9\\]=true}\relseif event.type == \"digiline\" then\r  port.b = mem.accept1\\[event.msg.hour\\]\r  port.d = mem.accept2\\[event.msg.hour\\]\rend]image_button[3.75,6;2.5,1;jeija_luac_runbutton.png;program;]image_button_exit[9.72,-0.25;0.425,0.4;jeija_close_window.png;exit;]label[0.1,5;]", ["code"] = "if event.type == \"program\" then\r  mem.accept1 = {[0]=true, [2]=true, [6]=true, [8]=true}\r  mem.accept2 = {[0]=true, [1]=true, [3]=true, [4]=true, [5]=true, [6]=true, [7]=true, [8]=true, [9]=true}\relseif event.type == \"digiline\" then\r  port.b = mem.accept1[event.msg.hour]\r  port.d = mem.accept2[event.msg.hour]\rend" } }, ["param2"] = 0, ["param1"] = 170 }, { ["y"] = 1, ["x"] = 2, ["name"] = "mesecons:wire_00110010_on", ["z"] = 13, ["meta"] = { ["inventory"] = {  }, ["fields"] = {  } }, ["param2"] = 0, ["param1"] = 187 }, { ["y"] = 1, ["x"] = 2, ["name"] = "default:glass", ["z"] = 14, ["meta"] = { ["inventory"] = {  }, ["fields"] = {  } }, ["param2"] = 0, ["param1"] = 170 }, { ["y"] = 1, ["x"] = 2, ["name"] = "mesecons:wire_01100010_on", ["z"] = 15, ["meta"] = { ["inventory"] = {  }, ["fields"] = {  } }, ["param2"] = 0, ["param1"] = 187 }, { ["y"] = 1, ["x"] = 2, ["name"] = "mesecons_luacontroller:luacontroller1010", ["z"] = 16, ["meta"] = { ["inventory"] = {  }, ["fields"] = { ["lc_memory"] = "return { [\"accept1\"] = { [0] = true, [2] = true, [8] = true, [6] = true }, [\"accept2\"] = { true, [0] = true, [7] = true, [8] = true, [3] = true, [9] = true, [4] = true, [5] = true, [6] = true } }", ["heat"] = "-1", ["formspec"] = "size[10,8]background[-0.2,-0.25;10.4,8.75;jeija_luac_background.png]textarea[0.2,0.6;10.2,5;code;;if event.type == \"program\" then\r  mem.accept1 = {\\[0\\]=true, \\[2\\]=true, \\[6\\]=true, \\[8\\]=true}\r  mem.accept2 = {\\[0\\]=true, \\[1\\]=true, \\[3\\]=true, \\[4\\]=true, \\[5\\]=true, \\[6\\]=true, \\[7\\]=true, \\[8\\]=true, \\[9\\]=true}\relseif event.type == \"digiline\" then\r  port.b = mem.accept1\\[event.msg.tenhour\\]\r  port.d = mem.accept2\\[event.msg.tenhour\\]\rend]image_button[3.75,6;2.5,1;jeija_luac_runbutton.png;program;]image_button_exit[9.72,-0.25;0.425,0.4;jeija_close_window.png;exit;]label[0.1,5;]", ["code"] = "if event.type == \"program\" then\r  mem.accept1 = {[0]=true, [2]=true, [6]=true, [8]=true}\r  mem.accept2 = {[0]=true, [1]=true, [3]=true, [4]=true, [5]=true, [6]=true, [7]=true, [8]=true, [9]=true}\relseif event.type == \"digiline\" then\r  port.b = mem.accept1[event.msg.tenhour]\r  port.d = mem.accept2[event.msg.tenhour]\rend" } }, ["param2"] = 0, ["param1"] = 170 }, { ["y"] = 1, ["x"] = 2, ["name"] = "mesecons:wire_00110010_on", ["z"] = 17, ["meta"] = { ["inventory"] = {  }, ["fields"] = {  } }, ["param2"] = 0, ["param1"] = 187 }, { ["y"] = 1, ["x"] = 2, ["name"] = "default:steelblock", ["z"] = 18, ["meta"] = { ["inventory"] = {  }, ["fields"] = {  } }, ["param2"] = 0, ["param1"] = 0 }, { ["y"] = 2, ["x"] = 2, ["name"] = "default:steelblock", ["z"] = 0, ["meta"] = { ["inventory"] = {  }, ["fields"] = {  } }, ["param2"] = 0, ["param1"] = 0 }, { ["y"] = 2, ["x"] = 2, ["name"] = "mesecons_extrawires:corner_on", ["z"] = 1, ["meta"] = { ["inventory"] = {  }, ["fields"] = {  } }, ["param2"] = 1, ["param1"] = 187 }, { ["y"] = 2, ["x"] = 2, ["name"] = "mesecons_luacontroller:luacontroller1011", ["z"] = 2, ["meta"] = { ["inventory"] = {  }, ["fields"] = { ["lc_memory"] = "return { [\"accept\"] = { [6] = true, [2] = true, [8] = true, [3] = true, [4] = true, [5] = true, [9] = true } }", ["heat"] = "4", ["formspec"] = "size[10,8]background[-0.2,-0.25;10.4,8.75;jeija_luac_background.png]textarea[0.2,0.6;10.2,5;code;;if event.type == \"program\" then\r  mem.accept = {\\[2\\]=true, \\[3\\]=true, \\[4\\]=true, \\[5\\]=true, \\[6\\]=true, \\[8\\]=true, \\[9\\]=true}\relseif event.type == \"digiline\" then\r  port.a = mem.accept\\[event.msg.minute\\]\r  port.b, port.d = port.a, port.a\rend]image_button[3.75,6;2.5,1;jeija_luac_runbutton.png;program;]image_button_exit[9.72,-0.25;0.425,0.4;jeija_close_window.png;exit;]label[0.1,5;]", ["code"] = "if event.type == \"program\" then\r  mem.accept = {[2]=true, [3]=true, [4]=true, [5]=true, [6]=true, [8]=true, [9]=true}\relseif event.type == \"digiline\" then\r  port.a = mem.accept[event.msg.minute]\r  port.b, port.d = port.a, port.a\rend" } }, ["param2"] = 0, ["param1"] = 187 }, { ["y"] = 2, ["x"] = 2, ["name"] = "mesecons_extrawires:corner_on", ["z"] = 3, ["meta"] = { ["inventory"] = {  }, ["fields"] = {  } }, ["param2"] = 0, ["param1"] = 187 }, { ["y"] = 2, ["x"] = 2, ["name"] = "default:glass", ["z"] = 4, ["meta"] = { ["inventory"] = {  }, ["fields"] = {  } }, ["param2"] = 0, ["param1"] = 170 }, { ["y"] = 2, ["x"] = 2, ["name"] = "mesecons_extrawires:corner_on", ["z"] = 5, ["meta"] = { ["inventory"] = {  }, ["fields"] = {  } }, ["param2"] = 1, ["param1"] = 187 }, { ["y"] = 2, ["x"] = 2, ["name"] = "mesecons_luacontroller:luacontroller1011", ["z"] = 6, ["meta"] = { ["inventory"] = {  }, ["fields"] = { ["lc_memory"] = "return { [\"accept\"] = { [6] = true, [2] = true, [8] = true, [3] = true, [4] = true, [5] = true, [9] = true } }", ["heat"] = "2", ["formspec"] = "size[10,8]background[-0.2,-0.25;10.4,8.75;jeija_luac_background.png]textarea[0.2,0.6;10.2,5;code;;if event.type == \"program\" then\r  mem.accept = {\\[2\\]=true, \\[3\\]=true, \\[4\\]=true, \\[5\\]=true, \\[6\\]=true, \\[8\\]=true, \\[9\\]=true}\relseif event.type == \"digiline\" then\r  port.a = mem.accept\\[event.msg.tenminute\\]\r  port.b, port.d = port.a, port.a\rend]image_button[3.75,6;2.5,1;jeija_luac_runbutton.png;program;]image_button_exit[9.72,-0.25;0.425,0.4;jeija_close_window.png;exit;]label[0.1,5;]", ["code"] = "if event.type == \"program\" then\r  mem.accept = {[2]=true, [3]=true, [4]=true, [5]=true, [6]=true, [8]=true, [9]=true}\relseif event.type == \"digiline\" then\r  port.a = mem.accept[event.msg.tenminute]\r  port.b, port.d = port.a, port.a\rend" } }, ["param2"] = 0, ["param1"] = 187 }, { ["y"] = 2, ["x"] = 2, ["name"] = "mesecons_extrawires:corner_on", ["z"] = 7, ["meta"] = { ["inventory"] = {  }, ["fields"] = {  } }, ["param2"] = 0, ["param1"] = 187 }, { ["y"] = 2, ["x"] = 2, ["name"] = "mesecons_luacontroller:luacontroller0000", ["z"] = 8, ["meta"] = { ["inventory"] = {  }, ["fields"] = { ["lc_memory"] = "return {  }", ["heat"] = "2", ["formspec"] = "size[10,8]background[-0.2,-0.25;10.4,8.75;jeija_luac_background.png]textarea[0.2,0.6;10.2,5;code;;if event.type == \"on\" then\
  digiline_send(\"clock\", \"GET\")\
end]image_button[3.75,6;2.5,1;jeija_luac_runbutton.png;program;]image_button_exit[9.72,-0.25;0.425,0.4;jeija_close_window.png;exit;]label[0.1,5;]", ["code"] = "if event.type == \"on\" then\
  digiline_send(\"clock\", \"GET\")\
end" } }, ["param2"] = 0, ["param1"] = 170 }, { ["y"] = 2, ["x"] = 2, ["name"] = "mesecons_blinkyplant:blinky_plant_off", ["z"] = 9, ["meta"] = { ["inventory"] = {  }, ["fields"] = {  } }, ["param2"] = 0, ["param1"] = 153 }, { ["y"] = 2, ["x"] = 2, ["name"] = "default:glass", ["z"] = 10, ["meta"] = { ["inventory"] = {  }, ["fields"] = {  } }, ["param2"] = 0, ["param1"] = 170 }, { ["y"] = 2, ["x"] = 2, ["name"] = "mesecons_extrawires:corner_on", ["z"] = 11, ["meta"] = { ["inventory"] = {  }, ["fields"] = {  } }, ["param2"] = 1, ["param1"] = 187 }, { ["y"] = 2, ["x"] = 2, ["name"] = "mesecons_luacontroller:luacontroller1011", ["z"] = 12, ["meta"] = { ["inventory"] = {  }, ["fields"] = { ["lc_memory"] = "return { [\"accept\"] = { [6] = true, [2] = true, [8] = true, [3] = true, [4] = true, [5] = true, [9] = true } }", ["heat"] = "2", ["formspec"] = "size[10,8]background[-0.2,-0.25;10.4,8.75;jeija_luac_background.png]textarea[0.2,0.6;10.2,5;code;;if event.type == \"program\" then\r  mem.accept = {\\[2\\]=true, \\[3\\]=true, \\[4\\]=true, \\[5\\]=true, \\[6\\]=true, \\[8\\]=true, \\[9\\]=true}\relseif event.type == \"digiline\" then\r  port.a = mem.accept\\[event.msg.hour\\]\r  port.b, port.d = port.a, port.a\rend]image_button[3.75,6;2.5,1;jeija_luac_runbutton.png;program;]image_button_exit[9.72,-0.25;0.425,0.4;jeija_close_window.png;exit;]label[0.1,5;]", ["code"] = "if event.type == \"program\" then\r  mem.accept = {[2]=true, [3]=true, [4]=true, [5]=true, [6]=true, [8]=true, [9]=true}\relseif event.type == \"digiline\" then\r  port.a = mem.accept[event.msg.hour]\r  port.b, port.d = port.a, port.a\rend" } }, ["param2"] = 0, ["param1"] = 187 }, { ["y"] = 2, ["x"] = 2, ["name"] = "mesecons_extrawires:corner_on", ["z"] = 13, ["meta"] = { ["inventory"] = {  }, ["fields"] = {  } }, ["param2"] = 0, ["param1"] = 187 }, { ["y"] = 2, ["x"] = 2, ["name"] = "default:glass", ["z"] = 14, ["meta"] = { ["inventory"] = {  }, ["fields"] = {  } }, ["param2"] = 0, ["param1"] = 170 }, { ["y"] = 2, ["x"] = 2, ["name"] = "mesecons_extrawires:corner_off", ["z"] = 15, ["meta"] = { ["inventory"] = {  }, ["fields"] = {  } }, ["param2"] = 1, ["param1"] = 187 }, { ["y"] = 2, ["x"] = 2, ["name"] = "mesecons_luacontroller:luacontroller0000", ["z"] = 16, ["meta"] = { ["inventory"] = {  }, ["fields"] = { ["lc_memory"] = "return { [\"accept\"] = { [6] = true, [2] = true, [8] = true, [3] = true, [4] = true, [5] = true, [9] = true } }", ["heat"] = "-1", ["formspec"] = "size[10,8]background[-0.2,-0.25;10.4,8.75;jeija_luac_background.png]textarea[0.2,0.6;10.2,5;code;;if event.type == \"program\" then\r  mem.accept = {\\[2\\]=true, \\[3\\]=true, \\[4\\]=true, \\[5\\]=true, \\[6\\]=true, \\[8\\]=true, \\[9\\]=true}\relseif event.type == \"digiline\" then\r  port.a = mem.accept\\[event.msg.tenhour\\]\r  port.b, port.d = port.a, port.a\rend]image_button[3.75,6;2.5,1;jeija_luac_runbutton.png;program;]image_button_exit[9.72,-0.25;0.425,0.4;jeija_close_window.png;exit;]label[0.1,5;]", ["code"] = "if event.type == \"program\" then\r  mem.accept = {[2]=true, [3]=true, [4]=true, [5]=true, [6]=true, [8]=true, [9]=true}\relseif event.type == \"digiline\" then\r  port.a = mem.accept[event.msg.tenhour]\r  port.b, port.d = port.a, port.a\rend" } }, ["param2"] = 0, ["param1"] = 170 }, { ["y"] = 2, ["x"] = 2, ["name"] = "mesecons_extrawires:corner_off", ["z"] = 17, ["meta"] = { ["inventory"] = {  }, ["fields"] = {  } }, ["param2"] = 0, ["param1"] = 187 }, { ["y"] = 2, ["x"] = 2, ["name"] = "default:steelblock", ["z"] = 18, ["meta"] = { ["inventory"] = {  }, ["fields"] = {  } }, ["param2"] = 0, ["param1"] = 0 }, { ["y"] = 3, ["x"] = 2, ["name"] = "default:steelblock", ["z"] = 0, ["meta"] = { ["inventory"] = {  }, ["fields"] = {  } }, ["param2"] = 0, ["param1"] = 0 }, { ["y"] = 3, ["x"] = 2, ["name"] = "mesecons:wire_01100010_on", ["z"] = 1, ["meta"] = { ["inventory"] = {  }, ["fields"] = {  } }, ["param2"] = 0, ["param1"] = 187 }, { ["y"] = 3, ["x"] = 2, ["name"] = "mesecons_luacontroller:luacontroller1010", ["z"] = 2, ["meta"] = { ["inventory"] = {  }, ["fields"] = { ["lc_memory"] = "return { [\"accept1\"] = { [0] = true, [8] = true, [6] = true, [4] = true, [5] = true, [9] = true }, [\"accept2\"] = { true, true, true, true, [0] = true, [9] = true, [7] = true, [8] = true } }", ["heat"] = "2", ["formspec"] = "size[10,8]background[-0.2,-0.25;10.4,8.75;jeija_luac_background.png]textarea[0.2,0.6;10.2,5;code;;if event.type == \"program\" then\r  mem.accept1 = {\\[0\\]=true, \\[4\\]=true, \\[5\\]=true, \\[6\\]=true, \\[8\\]=true, \\[9\\]=true}\r  mem.accept2 = {\\[0\\]=true, \\[1\\]=true, \\[2\\]=true, \\[3\\]=true, \\[4\\]=true, \\[7\\]=true, \\[8\\]=true, \\[9\\]=true}\relseif event.type == \"digiline\" then\r  port.b = mem.accept1\\[event.msg.minute\\]\r  port.d = mem.accept2\\[event.msg.minute\\]\rend]image_button[3.75,6;2.5,1;jeija_luac_runbutton.png;program;]image_button_exit[9.72,-0.25;0.425,0.4;jeija_close_window.png;exit;]label[0.1,5;]", ["code"] = "if event.type == \"program\" then\r  mem.accept1 = {[0]=true, [4]=true, [5]=true, [6]=true, [8]=true, [9]=true}\r  mem.accept2 = {[0]=true, [1]=true, [2]=true, [3]=true, [4]=true, [7]=true, [8]=true, [9]=true}\relseif event.type == \"digiline\" then\r  port.b = mem.accept1[event.msg.minute]\r  port.d = mem.accept2[event.msg.minute]\rend" } }, ["param2"] = 0, ["param1"] = 170 }, { ["y"] = 3, ["x"] = 2, ["name"] = "mesecons:wire_00110010_on", ["z"] = 3, ["meta"] = { ["inventory"] = {  }, ["fields"] = {  } }, ["param2"] = 0, ["param1"] = 187 }, { ["y"] = 3, ["x"] = 2, ["name"] = "default:glass", ["z"] = 4, ["meta"] = { ["inventory"] = {  }, ["fields"] = {  } }, ["param2"] = 0, ["param1"] = 170 }, { ["y"] = 3, ["x"] = 2, ["name"] = "mesecons:wire_01100010_off", ["z"] = 5, ["meta"] = { ["inventory"] = {  }, ["fields"] = {  } }, ["param2"] = 0, ["param1"] = 170 }, { ["y"] = 3, ["x"] = 2, ["name"] = "mesecons_luacontroller:luacontroller0010", ["z"] = 6, ["meta"] = { ["inventory"] = {  }, ["fields"] = { ["lc_memory"] = "return { [\"accept1\"] = { [0] = true, [8] = true, [6] = true, [4] = true, [5] = true, [9] = true }, [\"accept2\"] = { true, true, true, true, [0] = true, [9] = true, [7] = true, [8] = true } }", ["heat"] = "1", ["formspec"] = "size[10,8]background[-0.2,-0.25;10.4,8.75;jeija_luac_background.png]textarea[0.2,0.6;10.2,5;code;;if event.type == \"program\" then\r  mem.accept1 = {\\[0\\]=true, \\[4\\]=true, \\[5\\]=true, \\[6\\]=true, \\[8\\]=true, \\[9\\]=true}\r  mem.accept2 = {\\[0\\]=true, \\[1\\]=true, \\[2\\]=true, \\[3\\]=true, \\[4\\]=true, \\[7\\]=true, \\[8\\]=true, \\[9\\]=true}\relseif event.type == \"digiline\" then\r  port.b = mem.accept1\\[event.msg.tenminute\\]\r  port.d = mem.accept2\\[event.msg.tenminute\\]\rend]image_button[3.75,6;2.5,1;jeija_luac_runbutton.png;program;]image_button_exit[9.72,-0.25;0.425,0.4;jeija_close_window.png;exit;]label[0.1,5;]", ["code"] = "if event.type == \"program\" then\r  mem.accept1 = {[0]=true, [4]=true, [5]=true, [6]=true, [8]=true, [9]=true}\r  mem.accept2 = {[0]=true, [1]=true, [2]=true, [3]=true, [4]=true, [7]=true, [8]=true, [9]=true}\relseif event.type == \"digiline\" then\r  port.b = mem.accept1[event.msg.tenminute]\r  port.d = mem.accept2[event.msg.tenminute]\rend" } }, ["param2"] = 0, ["param1"] = 170 }, { ["y"] = 3, ["x"] = 2, ["name"] = "mesecons:wire_00110010_on", ["z"] = 7, ["meta"] = { ["inventory"] = {  }, ["fields"] = {  } }, ["param2"] = 0, ["param1"] = 187 }, { ["y"] = 3, ["x"] = 2, ["name"] = "default:glass", ["z"] = 8, ["meta"] = { ["inventory"] = {  }, ["fields"] = {  } }, ["param2"] = 0, ["param1"] = 170 }, { ["y"] = 3, ["x"] = 2, ["name"] = "default:glass", ["z"] = 9, ["meta"] = { ["inventory"] = {  }, ["fields"] = {  } }, ["param2"] = 0, ["param1"] = 153 }, { ["y"] = 3, ["x"] = 2, ["name"] = "default:glass", ["z"] = 10, ["meta"] = { ["inventory"] = {  }, ["fields"] = {  } }, ["param2"] = 0, ["param1"] = 153 }, { ["y"] = 3, ["x"] = 2, ["name"] = "mesecons:wire_01100010_off", ["z"] = 11, ["meta"] = { ["inventory"] = {  }, ["fields"] = {  } }, ["param2"] = 0, ["param1"] = 170 }, { ["y"] = 3, ["x"] = 2, ["name"] = "mesecons_luacontroller:luacontroller0010", ["z"] = 12, ["meta"] = { ["inventory"] = {  }, ["fields"] = { ["lc_memory"] = "return { [\"accept1\"] = { [0] = true, [8] = true, [6] = true, [4] = true, [5] = true, [9] = true }, [\"accept2\"] = { true, true, true, true, [0] = true, [9] = true, [7] = true, [8] = true } }", ["heat"] = "1", ["formspec"] = "size[10,8]background[-0.2,-0.25;10.4,8.75;jeija_luac_background.png]textarea[0.2,0.6;10.2,5;code;;if event.type == \"program\" then\r  mem.accept1 = {\\[0\\]=true, \\[4\\]=true, \\[5\\]=true, \\[6\\]=true, \\[8\\]=true, \\[9\\]=true}\r  mem.accept2 = {\\[0\\]=true, \\[1\\]=true, \\[2\\]=true, \\[3\\]=true, \\[4\\]=true, \\[7\\]=true, \\[8\\]=true, \\[9\\]=true}\relseif event.type == \"digiline\" then\r  port.b = mem.accept1\\[event.msg.hour\\]\r  port.d = mem.accept2\\[event.msg.hour\\]\rend]image_button[3.75,6;2.5,1;jeija_luac_runbutton.png;program;]image_button_exit[9.72,-0.25;0.425,0.4;jeija_close_window.png;exit;]label[0.1,5;]", ["code"] = "if event.type == \"program\" then\r  mem.accept1 = {[0]=true, [4]=true, [5]=true, [6]=true, [8]=true, [9]=true}\r  mem.accept2 = {[0]=true, [1]=true, [2]=true, [3]=true, [4]=true, [7]=true, [8]=true, [9]=true}\relseif event.type == \"digiline\" then\r  port.b = mem.accept1[event.msg.hour]\r  port.d = mem.accept2[event.msg.hour]\rend" } }, ["param2"] = 0, ["param1"] = 170 }, { ["y"] = 3, ["x"] = 2, ["name"] = "mesecons:wire_00110010_on", ["z"] = 13, ["meta"] = { ["inventory"] = {  }, ["fields"] = {  } }, ["param2"] = 0, ["param1"] = 187 }, { ["y"] = 3, ["x"] = 2, ["name"] = "default:glass", ["z"] = 14, ["meta"] = { ["inventory"] = {  }, ["fields"] = {  } }, ["param2"] = 0, ["param1"] = 170 }, { ["y"] = 3, ["x"] = 2, ["name"] = "mesecons:wire_01100010_on", ["z"] = 15, ["meta"] = { ["inventory"] = {  }, ["fields"] = {  } }, ["param2"] = 0, ["param1"] = 187 }, { ["y"] = 3, ["x"] = 2, ["name"] = "mesecons_luacontroller:luacontroller1010", ["z"] = 16, ["meta"] = { ["inventory"] = {  }, ["fields"] = { ["lc_memory"] = "return { [\"accept1\"] = { [0] = true, [8] = true, [9] = true, [4] = true, [5] = true, [6] = true }, [\"accept2\"] = { true, true, true, true, [0] = true, [8] = true, [9] = true, [7] = true } }", ["heat"] = "-1", ["formspec"] = "size[10,8]background[-0.2,-0.25;10.4,8.75;jeija_luac_background.png]textarea[0.2,0.6;10.2,5;code;;if event.type == \"program\" then\r  mem.accept1 = {\\[0\\]=true, \\[4\\]=true, \\[5\\]=true, \\[6\\]=true, \\[8\\]=true, \\[9\\]=true}\r  mem.accept2 = {\\[0\\]=true, \\[1\\]=true, \\[2\\]=true, \\[3\\]=true, \\[4\\]=true, \\[7\\]=true, \\[8\\]=true, \\[9\\]=true}\relseif event.type == \"digiline\" then\r  port.b = mem.accept1\\[event.msg.tenhour\\]\r  port.d = mem.accept2\\[event.msg.tenhour\\]\rend]image_button[3.75,6;2.5,1;jeija_luac_runbutton.png;program;]image_button_exit[9.72,-0.25;0.425,0.4;jeija_close_window.png;exit;]label[0.1,5;]", ["code"] = "if event.type == \"program\" then\r  mem.accept1 = {[0]=true, [4]=true, [5]=true, [6]=true, [8]=true, [9]=true}\r  mem.accept2 = {[0]=true, [1]=true, [2]=true, [3]=true, [4]=true, [7]=true, [8]=true, [9]=true}\relseif event.type == \"digiline\" then\r  port.b = mem.accept1[event.msg.tenhour]\r  port.d = mem.accept2[event.msg.tenhour]\rend" } }, ["param2"] = 0, ["param1"] = 170 }, { ["y"] = 3, ["x"] = 2, ["name"] = "mesecons:wire_00110010_on", ["z"] = 17, ["meta"] = { ["inventory"] = {  }, ["fields"] = {  } }, ["param2"] = 0, ["param1"] = 187 }, { ["y"] = 3, ["x"] = 2, ["name"] = "default:steelblock", ["z"] = 18, ["meta"] = { ["inventory"] = {  }, ["fields"] = {  } }, ["param2"] = 0, ["param1"] = 0 }, { ["y"] = 4, ["x"] = 2, ["name"] = "default:steelblock", ["z"] = 0, ["meta"] = { ["inventory"] = {  }, ["fields"] = {  } }, ["param2"] = 0, ["param1"] = 0 }, { ["y"] = 4, ["x"] = 2, ["name"] = "mesecons_extrawires:corner_on", ["z"] = 1, ["meta"] = { ["inventory"] = {  }, ["fields"] = {  } }, ["param2"] = 1, ["param1"] = 187 }, { ["y"] = 4, ["x"] = 2, ["name"] = "mesecons_luacontroller:luacontroller1011", ["z"] = 2, ["meta"] = { ["inventory"] = {  }, ["fields"] = { ["lc_memory"] = "return { [\"accept\"] = { [0] = true, [2] = true, [8] = true, [3] = true, [6] = true, [5] = true, [9] = true, [7] = true } }", ["heat"] = "0", ["formspec"] = "size[10,8]background[-0.2,-0.25;10.4,8.75;jeija_luac_background.png]textarea[0.2,0.6;10.2,5;code;;if event.type == \"program\" then\r  mem.accept = {\\[0\\]=true, \\[2\\]=true, \\[3\\]=true, \\[5\\]=true, \\[6\\]=true, \\[7\\]=true, \\[8\\]=true, \\[9\\]=true}\relseif event.type == \"digiline\" then\r  port.a = mem.accept\\[event.msg.minute\\]\r  port.b, port.d = port.a, port.a\rend]image_button[3.75,6;2.5,1;jeija_luac_runbutton.png;program;]image_button_exit[9.72,-0.25;0.425,0.4;jeija_close_window.png;exit;]label[0.1,5;]", ["code"] = "if event.type == \"program\" then\r  mem.accept = {[0]=true, [2]=true, [3]=true, [5]=true, [6]=true, [7]=true, [8]=true, [9]=true}\relseif event.type == \"digiline\" then\r  port.a = mem.accept[event.msg.minute]\r  port.b, port.d = port.a, port.a\rend" } }, ["param2"] = 0, ["param1"] = 187 }, { ["y"] = 4, ["x"] = 2, ["name"] = "mesecons_extrawires:corner_on", ["z"] = 3, ["meta"] = { ["inventory"] = {  }, ["fields"] = {  } }, ["param2"] = 0, ["param1"] = 187 }, { ["y"] = 4, ["x"] = 2, ["name"] = "default:glass", ["z"] = 4, ["meta"] = { ["inventory"] = {  }, ["fields"] = {  } }, ["param2"] = 0, ["param1"] = 170 }, { ["y"] = 4, ["x"] = 2, ["name"] = "mesecons_extrawires:corner_on", ["z"] = 5, ["meta"] = { ["inventory"] = {  }, ["fields"] = {  } }, ["param2"] = 1, ["param1"] = 187 }, { ["y"] = 4, ["x"] = 2, ["name"] = "mesecons_luacontroller:luacontroller1011", ["z"] = 6, ["meta"] = { ["inventory"] = {  }, ["fields"] = { ["lc_memory"] = "return { [\"accept\"] = { [0] = true, [2] = true, [8] = true, [3] = true, [6] = true, [5] = true, [9] = true, [7] = true } }", ["heat"] = "2", ["formspec"] = "size[10,8]background[-0.2,-0.25;10.4,8.75;jeija_luac_background.png]textarea[0.2,0.6;10.2,5;code;;if event.type == \"program\" then\r  mem.accept = {\\[0\\]=true, \\[2\\]=true, \\[3\\]=true, \\[5\\]=true, \\[6\\]=true, \\[7\\]=true, \\[8\\]=true, \\[9\\]=true}\relseif event.type == \"digiline\" then\r  port.a = mem.accept\\[event.msg.tenminute\\]\r  port.b, port.d = port.a, port.a\rend]image_button[3.75,6;2.5,1;jeija_luac_runbutton.png;program;]image_button_exit[9.72,-0.25;0.425,0.4;jeija_close_window.png;exit;]label[0.1,5;]", ["code"] = "if event.type == \"program\" then\r  mem.accept = {[0]=true, [2]=true, [3]=true, [5]=true, [6]=true, [7]=true, [8]=true, [9]=true}\relseif event.type == \"digiline\" then\r  port.a = mem.accept[event.msg.tenminute]\r  port.b, port.d = port.a, port.a\rend" } }, ["param2"] = 0, ["param1"] = 187 }, { ["y"] = 4, ["x"] = 2, ["name"] = "mesecons_extrawires:corner_on", ["z"] = 7, ["meta"] = { ["inventory"] = {  }, ["fields"] = {  } }, ["param2"] = 0, ["param1"] = 187 }, { ["y"] = 4, ["x"] = 2, ["name"] = "default:glass", ["z"] = 8, ["meta"] = { ["inventory"] = {  }, ["fields"] = {  } }, ["param2"] = 0, ["param1"] = 170 }, { ["y"] = 4, ["x"] = 2, ["name"] = "default:glass", ["z"] = 9, ["meta"] = { ["inventory"] = {  }, ["fields"] = {  } }, ["param2"] = 0, ["param1"] = 153 }, { ["y"] = 4, ["x"] = 2, ["name"] = "default:glass", ["z"] = 10, ["meta"] = { ["inventory"] = {  }, ["fields"] = {  } }, ["param2"] = 0, ["param1"] = 170 }, { ["y"] = 4, ["x"] = 2, ["name"] = "mesecons_extrawires:corner_on", ["z"] = 11, ["meta"] = { ["inventory"] = {  }, ["fields"] = {  } }, ["param2"] = 1, ["param1"] = 187 }, { ["y"] = 4, ["x"] = 2, ["name"] = "mesecons_luacontroller:luacontroller1011", ["z"] = 12, ["meta"] = { ["inventory"] = {  }, ["fields"] = { ["lc_memory"] = "return { [\"accept\"] = { [0] = true, [2] = true, [8] = true, [3] = true, [6] = true, [5] = true, [9] = true, [7] = true } }", ["heat"] = "2", ["formspec"] = "size[10,8]background[-0.2,-0.25;10.4,8.75;jeija_luac_background.png]textarea[0.2,0.6;10.2,5;code;;if event.type == \"program\" then\r  mem.accept = {\\[0\\]=true, \\[2\\]=true, \\[3\\]=true, \\[5\\]=true, \\[6\\]=true, \\[7\\]=true, \\[8\\]=true, \\[9\\]=true}\relseif event.type == \"digiline\" then\r  port.a = mem.accept\\[event.msg.hour\\]\r  port.b, port.d = port.a, port.a\rend]image_button[3.75,6;2.5,1;jeija_luac_runbutton.png;program;]image_button_exit[9.72,-0.25;0.425,0.4;jeija_close_window.png;exit;]label[0.1,5;]", ["code"] = "if event.type == \"program\" then\r  mem.accept = {[0]=true, [2]=true, [3]=true, [5]=true, [6]=true, [7]=true, [8]=true, [9]=true}\relseif event.type == \"digiline\" then\r  port.a = mem.accept[event.msg.hour]\r  port.b, port.d = port.a, port.a\rend" } }, ["param2"] = 0, ["param1"] = 187 }, { ["y"] = 4, ["x"] = 2, ["name"] = "mesecons_extrawires:corner_on", ["z"] = 13, ["meta"] = { ["inventory"] = {  }, ["fields"] = {  } }, ["param2"] = 0, ["param1"] = 187 }, { ["y"] = 4, ["x"] = 2, ["name"] = "default:glass", ["z"] = 14, ["meta"] = { ["inventory"] = {  }, ["fields"] = {  } }, ["param2"] = 0, ["param1"] = 170 }, { ["y"] = 4, ["x"] = 2, ["name"] = "mesecons_extrawires:corner_on", ["z"] = 15, ["meta"] = { ["inventory"] = {  }, ["fields"] = {  } }, ["param2"] = 1, ["param1"] = 187 }, { ["y"] = 4, ["x"] = 2, ["name"] = "mesecons_luacontroller:luacontroller1011", ["z"] = 16, ["meta"] = { ["inventory"] = {  }, ["fields"] = { ["lc_memory"] = "return { [\"accept\"] = { [0] = true, [2] = true, [8] = true, [3] = true, [7] = true, [9] = true, [5] = true, [6] = true } }", ["heat"] = "-1", ["formspec"] = "size[10,8]background[-0.2,-0.25;10.4,8.75;jeija_luac_background.png]textarea[0.2,0.6;10.2,5;code;;if event.type == \"program\" then\r  mem.accept = {\\[0\\]=true, \\[2\\]=true, \\[3\\]=true, \\[5\\]=true, \\[6\\]=true, \\[7\\]=true, \\[8\\]=true, \\[9\\]=true}\relseif event.type == \"digiline\" then\r  port.a = mem.accept\\[event.msg.tenhour\\]\r  port.b, port.d = port.a, port.a\rend]image_button[3.75,6;2.5,1;jeija_luac_runbutton.png;program;]image_button_exit[9.72,-0.25;0.425,0.4;jeija_close_window.png;exit;]label[0.1,5;]", ["code"] = "if event.type == \"program\" then\r  mem.accept = {[0]=true, [2]=true, [3]=true, [5]=true, [6]=true, [7]=true, [8]=true, [9]=true}\relseif event.type == \"digiline\" then\r  port.a = mem.accept[event.msg.tenhour]\r  port.b, port.d = port.a, port.a\rend" } }, ["param2"] = 0, ["param1"] = 187 }, { ["y"] = 4, ["x"] = 2, ["name"] = "mesecons_extrawires:corner_on", ["z"] = 17, ["meta"] = { ["inventory"] = {  }, ["fields"] = {  } }, ["param2"] = 0, ["param1"] = 187 }, { ["y"] = 4, ["x"] = 2, ["name"] = "default:steelblock", ["z"] = 18, ["meta"] = { ["inventory"] = {  }, ["fields"] = {  } }, ["param2"] = 0, ["param1"] = 0 }, { ["y"] = 5, ["x"] = 2, ["name"] = "default:steelblock", ["z"] = 0, ["meta"] = { ["inventory"] = {  }, ["fields"] = {  } }, ["param2"] = 0, ["param1"] = 0 }, { ["y"] = 5, ["x"] = 2, ["name"] = "default:steelblock", ["z"] = 1, ["meta"] = { ["inventory"] = {  }, ["fields"] = {  } }, ["param2"] = 0, ["param1"] = 0 }, { ["y"] = 5, ["x"] = 2, ["name"] = "default:steelblock", ["z"] = 2, ["meta"] = { ["inventory"] = {  }, ["fields"] = {  } }, ["param2"] = 0, ["param1"] = 0 }, { ["y"] = 5, ["x"] = 2, ["name"] = "default:steelblock", ["z"] = 3, ["meta"] = { ["inventory"] = {  }, ["fields"] = {  } }, ["param2"] = 0, ["param1"] = 0 }, { ["y"] = 5, ["x"] = 2, ["name"] = "default:steelblock", ["z"] = 4, ["meta"] = { ["inventory"] = {  }, ["fields"] = {  } }, ["param2"] = 0, ["param1"] = 0 }, { ["y"] = 5, ["x"] = 2, ["name"] = "default:steelblock", ["z"] = 5, ["meta"] = { ["inventory"] = {  }, ["fields"] = {  } }, ["param2"] = 0, ["param1"] = 0 }, { ["y"] = 5, ["x"] = 2, ["name"] = "default:steelblock", ["z"] = 6, ["meta"] = { ["inventory"] = {  }, ["fields"] = {  } }, ["param2"] = 0, ["param1"] = 0 }, { ["y"] = 5, ["x"] = 2, ["name"] = "default:steelblock", ["z"] = 7, ["meta"] = { ["inventory"] = {  }, ["fields"] = {  } }, ["param2"] = 0, ["param1"] = 0 }, { ["y"] = 5, ["x"] = 2, ["name"] = "default:steelblock", ["z"] = 8, ["meta"] = { ["inventory"] = {  }, ["fields"] = {  } }, ["param2"] = 0, ["param1"] = 0 }, { ["y"] = 5, ["x"] = 2, ["name"] = "default:steelblock", ["z"] = 9, ["meta"] = { ["inventory"] = {  }, ["fields"] = {  } }, ["param2"] = 0, ["param1"] = 0 }, { ["y"] = 5, ["x"] = 2, ["name"] = "default:steelblock", ["z"] = 10, ["meta"] = { ["inventory"] = {  }, ["fields"] = {  } }, ["param2"] = 0, ["param1"] = 0 }, { ["y"] = 5, ["x"] = 2, ["name"] = "default:steelblock", ["z"] = 11, ["meta"] = { ["inventory"] = {  }, ["fields"] = {  } }, ["param2"] = 0, ["param1"] = 0 }, { ["y"] = 5, ["x"] = 2, ["name"] = "default:steelblock", ["z"] = 12, ["meta"] = { ["inventory"] = {  }, ["fields"] = {  } }, ["param2"] = 0, ["param1"] = 0 }, { ["y"] = 5, ["x"] = 2, ["name"] = "default:steelblock", ["z"] = 13, ["meta"] = { ["inventory"] = {  }, ["fields"] = {  } }, ["param2"] = 0, ["param1"] = 0 }, { ["y"] = 5, ["x"] = 2, ["name"] = "default:steelblock", ["z"] = 14, ["meta"] = { ["inventory"] = {  }, ["fields"] = {  } }, ["param2"] = 0, ["param1"] = 0 }, { ["y"] = 5, ["x"] = 2, ["name"] = "default:steelblock", ["z"] = 15, ["meta"] = { ["inventory"] = {  }, ["fields"] = {  } }, ["param2"] = 0, ["param1"] = 0 }, { ["y"] = 5, ["x"] = 2, ["name"] = "default:steelblock", ["z"] = 16, ["meta"] = { ["inventory"] = {  }, ["fields"] = {  } }, ["param2"] = 0, ["param1"] = 0 }, { ["y"] = 5, ["x"] = 2, ["name"] = "default:steelblock", ["z"] = 17, ["meta"] = { ["inventory"] = {  }, ["fields"] = {  } }, ["param2"] = 0, ["param1"] = 0 }, { ["y"] = 5, ["x"] = 2, ["name"] = "default:steelblock", ["z"] = 18, ["meta"] = { ["inventory"] = {  }, ["fields"] = {  } }, ["param2"] = 0, ["param1"] = 0 }, { ["y"] = 0, ["x"] = 3, ["name"] = "default:steelblock", ["z"] = 0, ["meta"] = { ["inventory"] = {  }, ["fields"] = {  } }, ["param2"] = 0, ["param1"] = 0 }, { ["y"] = 0, ["x"] = 3, ["name"] = "default:glass", ["z"] = 1, ["meta"] = { ["inventory"] = {  }, ["fields"] = {  } }, ["param2"] = 0, ["param1"] = 170 }, { ["y"] = 0, ["x"] = 3, ["name"] = "default:glass", ["z"] = 2, ["meta"] = { ["inventory"] = {  }, ["fields"] = {  } }, ["param2"] = 0, ["param1"] = 170 }, { ["y"] = 0, ["x"] = 3, ["name"] = "digilines:wire_std_01010001", ["z"] = 3, ["meta"] = { ["inventory"] = {  }, ["fields"] = {  } }, ["param2"] = 0, ["param1"] = 170 }, { ["y"] = 0, ["x"] = 3, ["name"] = "digilines:wire_std_01010000", ["z"] = 4, ["meta"] = { ["inventory"] = {  }, ["fields"] = {  } }, ["param2"] = 0, ["param1"] = 153 }, { ["y"] = 0, ["x"] = 3, ["name"] = "digilines:wire_std_01010100", ["z"] = 5, ["meta"] = { ["inventory"] = {  }, ["fields"] = {  } }, ["param2"] = 0, ["param1"] = 170 }, { ["y"] = 0, ["x"] = 3, ["name"] = "digilines:wire_std_01110010", ["z"] = 6, ["meta"] = { ["inventory"] = {  }, ["fields"] = {  } }, ["param2"] = 0, ["param1"] = 170 }, { ["y"] = 0, ["x"] = 3, ["name"] = "digilines:wire_std_01010001", ["z"] = 7, ["meta"] = { ["inventory"] = {  }, ["fields"] = {  } }, ["param2"] = 0, ["param1"] = 170 }, { ["y"] = 0, ["x"] = 3, ["name"] = "digilines:wire_std_01010000", ["z"] = 8, ["meta"] = { ["inventory"] = {  }, ["fields"] = {  } }, ["param2"] = 0, ["param1"] = 153 }, { ["y"] = 0, ["x"] = 3, ["name"] = "digilines:wire_std_01110010", ["z"] = 9, ["meta"] = { ["inventory"] = {  }, ["fields"] = {  } }, ["param2"] = 0, ["param1"] = 136 }, { ["y"] = 0, ["x"] = 3, ["name"] = "digilines:wire_std_01010000", ["z"] = 10, ["meta"] = { ["inventory"] = {  }, ["fields"] = {  } }, ["param2"] = 0, ["param1"] = 153 }, { ["y"] = 0, ["x"] = 3, ["name"] = "digilines:wire_std_01010100", ["z"] = 11, ["meta"] = { ["inventory"] = {  }, ["fields"] = {  } }, ["param2"] = 0, ["param1"] = 170 }, { ["y"] = 0, ["x"] = 3, ["name"] = "digilines:wire_std_01110010", ["z"] = 12, ["meta"] = { ["inventory"] = {  }, ["fields"] = {  } }, ["param2"] = 0, ["param1"] = 170 }, { ["y"] = 0, ["x"] = 3, ["name"] = "digilines:wire_std_01010001", ["z"] = 13, ["meta"] = { ["inventory"] = {  }, ["fields"] = {  } }, ["param2"] = 0, ["param1"] = 170 }, { ["y"] = 0, ["x"] = 3, ["name"] = "digilines:wire_std_01010000", ["z"] = 14, ["meta"] = { ["inventory"] = {  }, ["fields"] = {  } }, ["param2"] = 0, ["param1"] = 153 }, { ["y"] = 0, ["x"] = 3, ["name"] = "digilines:wire_std_01010100", ["z"] = 15, ["meta"] = { ["inventory"] = {  }, ["fields"] = {  } }, ["param2"] = 0, ["param1"] = 170 }, { ["y"] = 0, ["x"] = 3, ["name"] = "default:glass", ["z"] = 16, ["meta"] = { ["inventory"] = {  }, ["fields"] = {  } }, ["param2"] = 0, ["param1"] = 170 }, { ["y"] = 0, ["x"] = 3, ["name"] = "default:glass", ["z"] = 17, ["meta"] = { ["inventory"] = {  }, ["fields"] = {  } }, ["param2"] = 0, ["param1"] = 170 }, { ["y"] = 0, ["x"] = 3, ["name"] = "default:steelblock", ["z"] = 18, ["meta"] = { ["inventory"] = {  }, ["fields"] = {  } }, ["param2"] = 0, ["param1"] = 0 }, { ["y"] = 1, ["x"] = 3, ["name"] = "default:steelblock", ["z"] = 0, ["meta"] = { ["inventory"] = {  }, ["fields"] = {  } }, ["param2"] = 0, ["param1"] = 0 }, { ["y"] = 1, ["x"] = 3, ["name"] = "default:glass", ["z"] = 1, ["meta"] = { ["inventory"] = {  }, ["fields"] = {  } }, ["param2"] = 0, ["param1"] = 170 }, { ["y"] = 1, ["x"] = 3, ["name"] = "digilines:wire_std_01100110", ["z"] = 2, ["meta"] = { ["inventory"] = {  }, ["fields"] = {  } }, ["param2"] = 0, ["param1"] = 153 }, { ["y"] = 1, ["x"] = 3, ["name"] = "default:glass", ["z"] = 3, ["meta"] = { ["inventory"] = {  }, ["fields"] = {  } }, ["param2"] = 0, ["param1"] = 153 }, { ["y"] = 1, ["x"] = 3, ["name"] = "default:glass", ["z"] = 4, ["meta"] = { ["inventory"] = {  }, ["fields"] = {  } }, ["param2"] = 0, ["param1"] = 153 }, { ["y"] = 1, ["x"] = 3, ["name"] = "default:glass", ["z"] = 5, ["meta"] = { ["inventory"] = {  }, ["fields"] = {  } }, ["param2"] = 0, ["param1"] = 170 }, { ["y"] = 1, ["x"] = 3, ["name"] = "digilines:wire_std_01110110", ["z"] = 6, ["meta"] = { ["inventory"] = {  }, ["fields"] = {  } }, ["param2"] = 0, ["param1"] = 153 }, { ["y"] = 1, ["x"] = 3, ["name"] = "default:glass", ["z"] = 7, ["meta"] = { ["inventory"] = {  }, ["fields"] = {  } }, ["param2"] = 0, ["param1"] = 153 }, { ["y"] = 1, ["x"] = 3, ["name"] = "default:glass", ["z"] = 8, ["meta"] = { ["inventory"] = {  }, ["fields"] = {  } }, ["param2"] = 0, ["param1"] = 136 }, { ["y"] = 1, ["x"] = 3, ["name"] = "default:glass", ["z"] = 9, ["meta"] = { ["inventory"] = {  }, ["fields"] = {  } }, ["param2"] = 0, ["param1"] = 136 }, { ["y"] = 1, ["x"] = 3, ["name"] = "default:glass", ["z"] = 10, ["meta"] = { ["inventory"] = {  }, ["fields"] = {  } }, ["param2"] = 0, ["param1"] = 153 }, { ["y"] = 1, ["x"] = 3, ["name"] = "default:glass", ["z"] = 11, ["meta"] = { ["inventory"] = {  }, ["fields"] = {  } }, ["param2"] = 0, ["param1"] = 170 }, { ["y"] = 1, ["x"] = 3, ["name"] = "digilines:wire_std_01110110", ["z"] = 12, ["meta"] = { ["inventory"] = {  }, ["fields"] = {  } }, ["param2"] = 0, ["param1"] = 153 }, { ["y"] = 1, ["x"] = 3, ["name"] = "default:glass", ["z"] = 13, ["meta"] = { ["inventory"] = {  }, ["fields"] = {  } }, ["param2"] = 0, ["param1"] = 170 }, { ["y"] = 1, ["x"] = 3, ["name"] = "default:glass", ["z"] = 14, ["meta"] = { ["inventory"] = {  }, ["fields"] = {  } }, ["param2"] = 0, ["param1"] = 153 }, { ["y"] = 1, ["x"] = 3, ["name"] = "default:glass", ["z"] = 15, ["meta"] = { ["inventory"] = {  }, ["fields"] = {  } }, ["param2"] = 0, ["param1"] = 170 }, { ["y"] = 1, ["x"] = 3, ["name"] = "digilines:wire_std_01110110", ["z"] = 16, ["meta"] = { ["inventory"] = {  }, ["fields"] = {  } }, ["param2"] = 0, ["param1"] = 153 }, { ["y"] = 1, ["x"] = 3, ["name"] = "default:glass", ["z"] = 17, ["meta"] = { ["inventory"] = {  }, ["fields"] = {  } }, ["param2"] = 0, ["param1"] = 170 }, { ["y"] = 1, ["x"] = 3, ["name"] = "default:steelblock", ["z"] = 18, ["meta"] = { ["inventory"] = {  }, ["fields"] = {  } }, ["param2"] = 0, ["param1"] = 0 }, { ["y"] = 2, ["x"] = 3, ["name"] = "default:steelblock", ["z"] = 0, ["meta"] = { ["inventory"] = {  }, ["fields"] = {  } }, ["param2"] = 0, ["param1"] = 0 }, { ["y"] = 2, ["x"] = 3, ["name"] = "default:glass", ["z"] = 1, ["meta"] = { ["inventory"] = {  }, ["fields"] = {  } }, ["param2"] = 0, ["param1"] = 170 }, { ["y"] = 2, ["x"] = 3, ["name"] = "digilines:wire_std_00010001", ["z"] = 3, ["meta"] = { ["inventory"] = {  }, ["fields"] = {  } }, ["param2"] = 0, ["param1"] = 170 }, { ["y"] = 2, ["x"] = 3, ["name"] = "default:glass", ["z"] = 4, ["meta"] = { ["inventory"] = {  }, ["fields"] = {  } }, ["param2"] = 0, ["param1"] = 153 }, { ["y"] = 2, ["x"] = 3, ["name"] = "default:glass", ["z"] = 5, ["meta"] = { ["inventory"] = {  }, ["fields"] = {  } }, ["param2"] = 0, ["param1"] = 170 }, { ["y"] = 2, ["x"] = 3, ["name"] = "digilines:wire_std_01010001", ["z"] = 7, ["meta"] = { ["inventory"] = {  }, ["fields"] = {  } }, ["param2"] = 0, ["param1"] = 170 }, { ["y"] = 2, ["x"] = 3, ["name"] = "digilines_rtc:rtc", ["z"] = 8, ["meta"] = { ["inventory"] = {  }, ["fields"] = { ["formspec"] = "field[channel;Channel;${channel}]", ["channel"] = "clock" } }, ["param2"] = 3, ["param1"] = 153 }, { ["y"] = 2, ["x"] = 3, ["name"] = "digilines:wire_std_00110000", ["z"] = 9, ["meta"] = { ["inventory"] = {  }, ["fields"] = {  } }, ["param2"] = 0, ["param1"] = 136 }, { ["y"] = 2, ["x"] = 3, ["name"] = "default:glass", ["z"] = 10, ["meta"] = { ["inventory"] = {  }, ["fields"] = {  } }, ["param2"] = 0, ["param1"] = 153 }, { ["y"] = 2, ["x"] = 3, ["name"] = "default:glass", ["z"] = 11, ["meta"] = { ["inventory"] = {  }, ["fields"] = {  } }, ["param2"] = 0, ["param1"] = 170 }, { ["y"] = 2, ["x"] = 3, ["name"] = "digilines:wire_std_00010001", ["z"] = 13, ["meta"] = { ["inventory"] = {  }, ["fields"] = {  } }, ["param2"] = 0, ["param1"] = 170 }, { ["y"] = 2, ["x"] = 3, ["name"] = "default:glass", ["z"] = 14, ["meta"] = { ["inventory"] = {  }, ["fields"] = {  } }, ["param2"] = 0, ["param1"] = 153 }, { ["y"] = 2, ["x"] = 3, ["name"] = "default:glass", ["z"] = 15, ["meta"] = { ["inventory"] = {  }, ["fields"] = {  } }, ["param2"] = 0, ["param1"] = 170 }, { ["y"] = 2, ["x"] = 3, ["name"] = "digilines:wire_std_00010001", ["z"] = 17, ["meta"] = { ["inventory"] = {  }, ["fields"] = {  } }, ["param2"] = 0, ["param1"] = 170 }, { ["y"] = 2, ["x"] = 3, ["name"] = "default:steelblock", ["z"] = 18, ["meta"] = { ["inventory"] = {  }, ["fields"] = {  } }, ["param2"] = 0, ["param1"] = 0 }, { ["y"] = 3, ["x"] = 3, ["name"] = "default:steelblock", ["z"] = 0, ["meta"] = { ["inventory"] = {  }, ["fields"] = {  } }, ["param2"] = 0, ["param1"] = 0 }, { ["y"] = 3, ["x"] = 3, ["name"] = "default:glass", ["z"] = 1, ["meta"] = { ["inventory"] = {  }, ["fields"] = {  } }, ["param2"] = 0, ["param1"] = 170 }, { ["y"] = 3, ["x"] = 3, ["name"] = "digilines:wire_std_01100010", ["z"] = 2, ["meta"] = { ["inventory"] = {  }, ["fields"] = {  } }, ["param2"] = 0, ["param1"] = 153 }, { ["y"] = 3, ["x"] = 3, ["name"] = "default:glass", ["z"] = 3, ["meta"] = { ["inventory"] = {  }, ["fields"] = {  } }, ["param2"] = 0, ["param1"] = 170 }, { ["y"] = 3, ["x"] = 3, ["name"] = "default:glass", ["z"] = 4, ["meta"] = { ["inventory"] = {  }, ["fields"] = {  } }, ["param2"] = 0, ["param1"] = 153 }, { ["y"] = 3, ["x"] = 3, ["name"] = "default:glass", ["z"] = 5, ["meta"] = { ["inventory"] = {  }, ["fields"] = {  } }, ["param2"] = 0, ["param1"] = 153 }, { ["y"] = 3, ["x"] = 3, ["name"] = "digilines:wire_std_01100010", ["z"] = 6, ["meta"] = { ["inventory"] = {  }, ["fields"] = {  } }, ["param2"] = 0, ["param1"] = 153 }, { ["y"] = 3, ["x"] = 3, ["name"] = "default:glass", ["z"] = 7, ["meta"] = { ["inventory"] = {  }, ["fields"] = {  } }, ["param2"] = 0, ["param1"] = 170 }, { ["y"] = 3, ["x"] = 3, ["name"] = "default:glass", ["z"] = 8, ["meta"] = { ["inventory"] = {  }, ["fields"] = {  } }, ["param2"] = 0, ["param1"] = 153 }, { ["y"] = 3, ["x"] = 3, ["name"] = "default:glass", ["z"] = 9, ["meta"] = { ["inventory"] = {  }, ["fields"] = {  } }, ["param2"] = 0, ["param1"] = 136 }, { ["y"] = 3, ["x"] = 3, ["name"] = "default:glass", ["z"] = 10, ["meta"] = { ["inventory"] = {  }, ["fields"] = {  } }, ["param2"] = 0, ["param1"] = 136 }, { ["y"] = 3, ["x"] = 3, ["name"] = "default:glass", ["z"] = 11, ["meta"] = { ["inventory"] = {  }, ["fields"] = {  } }, ["param2"] = 0, ["param1"] = 153 }, { ["y"] = 3, ["x"] = 3, ["name"] = "digilines:wire_std_01100010", ["z"] = 12, ["meta"] = { ["inventory"] = {  }, ["fields"] = {  } }, ["param2"] = 0, ["param1"] = 153 }, { ["y"] = 3, ["x"] = 3, ["name"] = "default:glass", ["z"] = 13, ["meta"] = { ["inventory"] = {  }, ["fields"] = {  } }, ["param2"] = 0, ["param1"] = 170 }, { ["y"] = 3, ["x"] = 3, ["name"] = "default:glass", ["z"] = 14, ["meta"] = { ["inventory"] = {  }, ["fields"] = {  } }, ["param2"] = 0, ["param1"] = 153 }, { ["y"] = 3, ["x"] = 3, ["name"] = "default:glass", ["z"] = 15, ["meta"] = { ["inventory"] = {  }, ["fields"] = {  } }, ["param2"] = 0, ["param1"] = 170 }, { ["y"] = 3, ["x"] = 3, ["name"] = "digilines:wire_std_01100010", ["z"] = 16, ["meta"] = { ["inventory"] = {  }, ["fields"] = {  } }, ["param2"] = 0, ["param1"] = 153 }, { ["y"] = 3, ["x"] = 3, ["name"] = "default:glass", ["z"] = 17, ["meta"] = { ["inventory"] = {  }, ["fields"] = {  } }, ["param2"] = 0, ["param1"] = 170 }, { ["y"] = 3, ["x"] = 3, ["name"] = "default:steelblock", ["z"] = 18, ["meta"] = { ["inventory"] = {  }, ["fields"] = {  } }, ["param2"] = 0, ["param1"] = 0 }, { ["y"] = 4, ["x"] = 3, ["name"] = "default:steelblock", ["z"] = 0, ["meta"] = { ["inventory"] = {  }, ["fields"] = {  } }, ["param2"] = 0, ["param1"] = 0 }, { ["y"] = 4, ["x"] = 3, ["name"] = "default:glass", ["z"] = 1, ["meta"] = { ["inventory"] = {  }, ["fields"] = {  } }, ["param2"] = 0, ["param1"] = 170 }, { ["y"] = 4, ["x"] = 3, ["name"] = "default:glass", ["z"] = 2, ["meta"] = { ["inventory"] = {  }, ["fields"] = {  } }, ["param2"] = 0, ["param1"] = 170 }, { ["y"] = 4, ["x"] = 3, ["name"] = "default:glass", ["z"] = 3, ["meta"] = { ["inventory"] = {  }, ["fields"] = {  } }, ["param2"] = 0, ["param1"] = 170 }, { ["y"] = 4, ["x"] = 3, ["name"] = "default:glass", ["z"] = 4, ["meta"] = { ["inventory"] = {  }, ["fields"] = {  } }, ["param2"] = 0, ["param1"] = 153 }, { ["y"] = 4, ["x"] = 3, ["name"] = "default:glass", ["z"] = 5, ["meta"] = { ["inventory"] = {  }, ["fields"] = {  } }, ["param2"] = 0, ["param1"] = 170 }, { ["y"] = 4, ["x"] = 3, ["name"] = "default:glass", ["z"] = 6, ["meta"] = { ["inventory"] = {  }, ["fields"] = {  } }, ["param2"] = 0, ["param1"] = 170 }, { ["y"] = 4, ["x"] = 3, ["name"] = "default:glass", ["z"] = 7, ["meta"] = { ["inventory"] = {  }, ["fields"] = {  } }, ["param2"] = 0, ["param1"] = 170 }, { ["y"] = 4, ["x"] = 3, ["name"] = "default:glass", ["z"] = 8, ["meta"] = { ["inventory"] = {  }, ["fields"] = {  } }, ["param2"] = 0, ["param1"] = 153 }, { ["y"] = 4, ["x"] = 3, ["name"] = "default:glass", ["z"] = 9, ["meta"] = { ["inventory"] = {  }, ["fields"] = {  } }, ["param2"] = 0, ["param1"] = 136 }, { ["y"] = 4, ["x"] = 3, ["name"] = "default:glass", ["z"] = 10, ["meta"] = { ["inventory"] = {  }, ["fields"] = {  } }, ["param2"] = 0, ["param1"] = 153 }, { ["y"] = 4, ["x"] = 3, ["name"] = "default:glass", ["z"] = 11, ["meta"] = { ["inventory"] = {  }, ["fields"] = {  } }, ["param2"] = 0, ["param1"] = 170 }, { ["y"] = 4, ["x"] = 3, ["name"] = "default:glass", ["z"] = 12, ["meta"] = { ["inventory"] = {  }, ["fields"] = {  } }, ["param2"] = 0, ["param1"] = 170 }, { ["y"] = 4, ["x"] = 3, ["name"] = "default:glass", ["z"] = 13, ["meta"] = { ["inventory"] = {  }, ["fields"] = {  } }, ["param2"] = 0, ["param1"] = 170 }, { ["y"] = 4, ["x"] = 3, ["name"] = "default:glass", ["z"] = 14, ["meta"] = { ["inventory"] = {  }, ["fields"] = {  } }, ["param2"] = 0, ["param1"] = 153 }, { ["y"] = 4, ["x"] = 3, ["name"] = "default:glass", ["z"] = 15, ["meta"] = { ["inventory"] = {  }, ["fields"] = {  } }, ["param2"] = 0, ["param1"] = 170 }, { ["y"] = 4, ["x"] = 3, ["name"] = "default:glass", ["z"] = 16, ["meta"] = { ["inventory"] = {  }, ["fields"] = {  } }, ["param2"] = 0, ["param1"] = 170 }, { ["y"] = 4, ["x"] = 3, ["name"] = "default:glass", ["z"] = 17, ["meta"] = { ["inventory"] = {  }, ["fields"] = {  } }, ["param2"] = 0, ["param1"] = 170 }, { ["y"] = 4, ["x"] = 3, ["name"] = "default:steelblock", ["z"] = 18, ["meta"] = { ["inventory"] = {  }, ["fields"] = {  } }, ["param2"] = 0, ["param1"] = 0 }, { ["y"] = 5, ["x"] = 3, ["name"] = "default:steelblock", ["z"] = 0, ["meta"] = { ["inventory"] = {  }, ["fields"] = {  } }, ["param2"] = 0, ["param1"] = 0 }, { ["y"] = 5, ["x"] = 3, ["name"] = "default:steelblock", ["z"] = 1, ["meta"] = { ["inventory"] = {  }, ["fields"] = {  } }, ["param2"] = 0, ["param1"] = 0 }, { ["y"] = 5, ["x"] = 3, ["name"] = "default:steelblock", ["z"] = 2, ["meta"] = { ["inventory"] = {  }, ["fields"] = {  } }, ["param2"] = 0, ["param1"] = 0 }, { ["y"] = 5, ["x"] = 3, ["name"] = "default:steelblock", ["z"] = 3, ["meta"] = { ["inventory"] = {  }, ["fields"] = {  } }, ["param2"] = 0, ["param1"] = 0 }, { ["y"] = 5, ["x"] = 3, ["name"] = "default:steelblock", ["z"] = 4, ["meta"] = { ["inventory"] = {  }, ["fields"] = {  } }, ["param2"] = 0, ["param1"] = 0 }, { ["y"] = 5, ["x"] = 3, ["name"] = "default:steelblock", ["z"] = 5, ["meta"] = { ["inventory"] = {  }, ["fields"] = {  } }, ["param2"] = 0, ["param1"] = 0 }, { ["y"] = 5, ["x"] = 3, ["name"] = "default:steelblock", ["z"] = 6, ["meta"] = { ["inventory"] = {  }, ["fields"] = {  } }, ["param2"] = 0, ["param1"] = 0 }, { ["y"] = 5, ["x"] = 3, ["name"] = "default:steelblock", ["z"] = 7, ["meta"] = { ["inventory"] = {  }, ["fields"] = {  } }, ["param2"] = 0, ["param1"] = 0 }, { ["y"] = 5, ["x"] = 3, ["name"] = "default:steelblock", ["z"] = 8, ["meta"] = { ["inventory"] = {  }, ["fields"] = {  } }, ["param2"] = 0, ["param1"] = 0 }, { ["y"] = 5, ["x"] = 3, ["name"] = "default:steelblock", ["z"] = 9, ["meta"] = { ["inventory"] = {  }, ["fields"] = {  } }, ["param2"] = 0, ["param1"] = 0 }, { ["y"] = 5, ["x"] = 3, ["name"] = "default:steelblock", ["z"] = 10, ["meta"] = { ["inventory"] = {  }, ["fields"] = {  } }, ["param2"] = 0, ["param1"] = 0 }, { ["y"] = 5, ["x"] = 3, ["name"] = "default:steelblock", ["z"] = 11, ["meta"] = { ["inventory"] = {  }, ["fields"] = {  } }, ["param2"] = 0, ["param1"] = 0 }, { ["y"] = 5, ["x"] = 3, ["name"] = "default:steelblock", ["z"] = 12, ["meta"] = { ["inventory"] = {  }, ["fields"] = {  } }, ["param2"] = 0, ["param1"] = 0 }, { ["y"] = 5, ["x"] = 3, ["name"] = "default:steelblock", ["z"] = 13, ["meta"] = { ["inventory"] = {  }, ["fields"] = {  } }, ["param2"] = 0, ["param1"] = 0 }, { ["y"] = 5, ["x"] = 3, ["name"] = "default:steelblock", ["z"] = 14, ["meta"] = { ["inventory"] = {  }, ["fields"] = {  } }, ["param2"] = 0, ["param1"] = 0 }, { ["y"] = 5, ["x"] = 3, ["name"] = "default:steelblock", ["z"] = 15, ["meta"] = { ["inventory"] = {  }, ["fields"] = {  } }, ["param2"] = 0, ["param1"] = 0 }, { ["y"] = 5, ["x"] = 3, ["name"] = "default:steelblock", ["z"] = 16, ["meta"] = { ["inventory"] = {  }, ["fields"] = {  } }, ["param2"] = 0, ["param1"] = 0 }, { ["y"] = 5, ["x"] = 3, ["name"] = "default:steelblock", ["z"] = 17, ["meta"] = { ["inventory"] = {  }, ["fields"] = {  } }, ["param2"] = 0, ["param1"] = 0 }, { ["y"] = 5, ["x"] = 3, ["name"] = "default:steelblock", ["z"] = 18, ["meta"] = { ["inventory"] = {  }, ["fields"] = {  } }, ["param2"] = 0, ["param1"] = 0 }, { ["y"] = 0, ["x"] = 4, ["name"] = "default:steelblock", ["z"] = 0, ["meta"] = { ["inventory"] = {  }, ["fields"] = {  } }, ["param2"] = 0, ["param1"] = 0 }, { ["y"] = 0, ["x"] = 4, ["name"] = "default:steelblock", ["z"] = 1, ["meta"] = { ["inventory"] = {  }, ["fields"] = {  } }, ["param2"] = 0, ["param1"] = 0 }, { ["y"] = 0, ["x"] = 4, ["name"] = "default:steelblock", ["z"] = 2, ["meta"] = { ["inventory"] = {  }, ["fields"] = {  } }, ["param2"] = 0, ["param1"] = 0 }, { ["y"] = 0, ["x"] = 4, ["name"] = "default:steelblock", ["z"] = 3, ["meta"] = { ["inventory"] = {  }, ["fields"] = {  } }, ["param2"] = 0, ["param1"] = 0 }, { ["y"] = 0, ["x"] = 4, ["name"] = "default:steelblock", ["z"] = 4, ["meta"] = { ["inventory"] = {  }, ["fields"] = {  } }, ["param2"] = 0, ["param1"] = 0 }, { ["y"] = 0, ["x"] = 4, ["name"] = "default:steelblock", ["z"] = 5, ["meta"] = { ["inventory"] = {  }, ["fields"] = {  } }, ["param2"] = 0, ["param1"] = 0 }, { ["y"] = 0, ["x"] = 4, ["name"] = "default:steelblock", ["z"] = 6, ["meta"] = { ["inventory"] = {  }, ["fields"] = {  } }, ["param2"] = 0, ["param1"] = 0 }, { ["y"] = 0, ["x"] = 4, ["name"] = "default:steelblock", ["z"] = 7, ["meta"] = { ["inventory"] = {  }, ["fields"] = {  } }, ["param2"] = 0, ["param1"] = 0 }, { ["y"] = 0, ["x"] = 4, ["name"] = "default:steelblock", ["z"] = 8, ["meta"] = { ["inventory"] = {  }, ["fields"] = {  } }, ["param2"] = 0, ["param1"] = 0 }, { ["y"] = 0, ["x"] = 4, ["name"] = "default:steelblock", ["z"] = 9, ["meta"] = { ["inventory"] = {  }, ["fields"] = {  } }, ["param2"] = 0, ["param1"] = 0 }, { ["y"] = 0, ["x"] = 4, ["name"] = "default:steelblock", ["z"] = 10, ["meta"] = { ["inventory"] = {  }, ["fields"] = {  } }, ["param2"] = 0, ["param1"] = 0 }, { ["y"] = 0, ["x"] = 4, ["name"] = "default:steelblock", ["z"] = 11, ["meta"] = { ["inventory"] = {  }, ["fields"] = {  } }, ["param2"] = 0, ["param1"] = 0 }, { ["y"] = 0, ["x"] = 4, ["name"] = "default:steelblock", ["z"] = 12, ["meta"] = { ["inventory"] = {  }, ["fields"] = {  } }, ["param2"] = 0, ["param1"] = 0 }, { ["y"] = 0, ["x"] = 4, ["name"] = "default:steelblock", ["z"] = 13, ["meta"] = { ["inventory"] = {  }, ["fields"] = {  } }, ["param2"] = 0, ["param1"] = 0 }, { ["y"] = 0, ["x"] = 4, ["name"] = "default:steelblock", ["z"] = 14, ["meta"] = { ["inventory"] = {  }, ["fields"] = {  } }, ["param2"] = 0, ["param1"] = 0 }, { ["y"] = 0, ["x"] = 4, ["name"] = "default:steelblock", ["z"] = 15, ["meta"] = { ["inventory"] = {  }, ["fields"] = {  } }, ["param2"] = 0, ["param1"] = 0 }, { ["y"] = 0, ["x"] = 4, ["name"] = "default:steelblock", ["z"] = 16, ["meta"] = { ["inventory"] = {  }, ["fields"] = {  } }, ["param2"] = 0, ["param1"] = 0 }, { ["y"] = 0, ["x"] = 4, ["name"] = "default:steelblock", ["z"] = 17, ["meta"] = { ["inventory"] = {  }, ["fields"] = {  } }, ["param2"] = 0, ["param1"] = 0 }, { ["y"] = 0, ["x"] = 4, ["name"] = "default:steelblock", ["z"] = 18, ["meta"] = { ["inventory"] = {  }, ["fields"] = {  } }, ["param2"] = 0, ["param1"] = 0 }, { ["y"] = 1, ["x"] = 4, ["name"] = "default:steelblock", ["z"] = 0, ["meta"] = { ["inventory"] = {  }, ["fields"] = {  } }, ["param2"] = 0, ["param1"] = 0 }, { ["y"] = 1, ["x"] = 4, ["name"] = "default:steelblock", ["z"] = 1, ["meta"] = { ["inventory"] = {  }, ["fields"] = {  } }, ["param2"] = 0, ["param1"] = 0 }, { ["y"] = 1, ["x"] = 4, ["name"] = "default:steelblock", ["z"] = 2, ["meta"] = { ["inventory"] = {  }, ["fields"] = {  } }, ["param2"] = 0, ["param1"] = 0 }, { ["y"] = 1, ["x"] = 4, ["name"] = "default:steelblock", ["z"] = 3, ["meta"] = { ["inventory"] = {  }, ["fields"] = {  } }, ["param2"] = 0, ["param1"] = 0 }, { ["y"] = 1, ["x"] = 4, ["name"] = "default:steelblock", ["z"] = 4, ["meta"] = { ["inventory"] = {  }, ["fields"] = {  } }, ["param2"] = 0, ["param1"] = 0 }, { ["y"] = 1, ["x"] = 4, ["name"] = "default:steelblock", ["z"] = 5, ["meta"] = { ["inventory"] = {  }, ["fields"] = {  } }, ["param2"] = 0, ["param1"] = 0 }, { ["y"] = 1, ["x"] = 4, ["name"] = "default:steelblock", ["z"] = 6, ["meta"] = { ["inventory"] = {  }, ["fields"] = {  } }, ["param2"] = 0, ["param1"] = 0 }, { ["y"] = 1, ["x"] = 4, ["name"] = "default:steelblock", ["z"] = 7, ["meta"] = { ["inventory"] = {  }, ["fields"] = {  } }, ["param2"] = 0, ["param1"] = 0 }, { ["y"] = 1, ["x"] = 4, ["name"] = "default:steelblock", ["z"] = 8, ["meta"] = { ["inventory"] = {  }, ["fields"] = {  } }, ["param2"] = 0, ["param1"] = 0 }, { ["y"] = 1, ["x"] = 4, ["name"] = "default:steelblock", ["z"] = 9, ["meta"] = { ["inventory"] = {  }, ["fields"] = {  } }, ["param2"] = 0, ["param1"] = 0 }, { ["y"] = 1, ["x"] = 4, ["name"] = "default:steelblock", ["z"] = 10, ["meta"] = { ["inventory"] = {  }, ["fields"] = {  } }, ["param2"] = 0, ["param1"] = 0 }, { ["y"] = 1, ["x"] = 4, ["name"] = "default:steelblock", ["z"] = 11, ["meta"] = { ["inventory"] = {  }, ["fields"] = {  } }, ["param2"] = 0, ["param1"] = 0 }, { ["y"] = 1, ["x"] = 4, ["name"] = "default:steelblock", ["z"] = 12, ["meta"] = { ["inventory"] = {  }, ["fields"] = {  } }, ["param2"] = 0, ["param1"] = 0 }, { ["y"] = 1, ["x"] = 4, ["name"] = "default:steelblock", ["z"] = 13, ["meta"] = { ["inventory"] = {  }, ["fields"] = {  } }, ["param2"] = 0, ["param1"] = 0 }, { ["y"] = 1, ["x"] = 4, ["name"] = "default:steelblock", ["z"] = 14, ["meta"] = { ["inventory"] = {  }, ["fields"] = {  } }, ["param2"] = 0, ["param1"] = 0 }, { ["y"] = 1, ["x"] = 4, ["name"] = "default:steelblock", ["z"] = 15, ["meta"] = { ["inventory"] = {  }, ["fields"] = {  } }, ["param2"] = 0, ["param1"] = 0 }, { ["y"] = 1, ["x"] = 4, ["name"] = "default:steelblock", ["z"] = 16, ["meta"] = { ["inventory"] = {  }, ["fields"] = {  } }, ["param2"] = 0, ["param1"] = 0 }, { ["y"] = 1, ["x"] = 4, ["name"] = "default:steelblock", ["z"] = 17, ["meta"] = { ["inventory"] = {  }, ["fields"] = {  } }, ["param2"] = 0, ["param1"] = 0 }, { ["y"] = 1, ["x"] = 4, ["name"] = "default:steelblock", ["z"] = 18, ["meta"] = { ["inventory"] = {  }, ["fields"] = {  } }, ["param2"] = 0, ["param1"] = 0 }, { ["y"] = 2, ["x"] = 4, ["name"] = "default:steelblock", ["z"] = 0, ["meta"] = { ["inventory"] = {  }, ["fields"] = {  } }, ["param2"] = 0, ["param1"] = 0 }, { ["y"] = 2, ["x"] = 4, ["name"] = "default:steelblock", ["z"] = 1, ["meta"] = { ["inventory"] = {  }, ["fields"] = {  } }, ["param2"] = 0, ["param1"] = 0 }, { ["y"] = 2, ["x"] = 4, ["name"] = "default:steelblock", ["z"] = 2, ["meta"] = { ["inventory"] = {  }, ["fields"] = {  } }, ["param2"] = 0, ["param1"] = 0 }, { ["y"] = 2, ["x"] = 4, ["name"] = "default:steelblock", ["z"] = 3, ["meta"] = { ["inventory"] = {  }, ["fields"] = {  } }, ["param2"] = 0, ["param1"] = 0 }, { ["y"] = 2, ["x"] = 4, ["name"] = "default:steelblock", ["z"] = 4, ["meta"] = { ["inventory"] = {  }, ["fields"] = {  } }, ["param2"] = 0, ["param1"] = 0 }, { ["y"] = 2, ["x"] = 4, ["name"] = "default:steelblock", ["z"] = 5, ["meta"] = { ["inventory"] = {  }, ["fields"] = {  } }, ["param2"] = 0, ["param1"] = 0 }, { ["y"] = 2, ["x"] = 4, ["name"] = "default:steelblock", ["z"] = 6, ["meta"] = { ["inventory"] = {  }, ["fields"] = {  } }, ["param2"] = 0, ["param1"] = 0 }, { ["y"] = 2, ["x"] = 4, ["name"] = "default:steelblock", ["z"] = 7, ["meta"] = { ["inventory"] = {  }, ["fields"] = {  } }, ["param2"] = 0, ["param1"] = 0 }, { ["y"] = 2, ["x"] = 4, ["name"] = "default:steelblock", ["z"] = 8, ["meta"] = { ["inventory"] = {  }, ["fields"] = {  } }, ["param2"] = 0, ["param1"] = 0 }, { ["y"] = 2, ["x"] = 4, ["name"] = "default:steelblock", ["z"] = 9, ["meta"] = { ["inventory"] = {  }, ["fields"] = {  } }, ["param2"] = 0, ["param1"] = 0 }, { ["y"] = 2, ["x"] = 4, ["name"] = "default:steelblock", ["z"] = 10, ["meta"] = { ["inventory"] = {  }, ["fields"] = {  } }, ["param2"] = 0, ["param1"] = 0 }, { ["y"] = 2, ["x"] = 4, ["name"] = "default:steelblock", ["z"] = 11, ["meta"] = { ["inventory"] = {  }, ["fields"] = {  } }, ["param2"] = 0, ["param1"] = 0 }, { ["y"] = 2, ["x"] = 4, ["name"] = "default:steelblock", ["z"] = 12, ["meta"] = { ["inventory"] = {  }, ["fields"] = {  } }, ["param2"] = 0, ["param1"] = 0 }, { ["y"] = 2, ["x"] = 4, ["name"] = "default:steelblock", ["z"] = 13, ["meta"] = { ["inventory"] = {  }, ["fields"] = {  } }, ["param2"] = 0, ["param1"] = 0 }, { ["y"] = 2, ["x"] = 4, ["name"] = "default:steelblock", ["z"] = 14, ["meta"] = { ["inventory"] = {  }, ["fields"] = {  } }, ["param2"] = 0, ["param1"] = 0 }, { ["y"] = 2, ["x"] = 4, ["name"] = "default:steelblock", ["z"] = 15, ["meta"] = { ["inventory"] = {  }, ["fields"] = {  } }, ["param2"] = 0, ["param1"] = 0 }, { ["y"] = 2, ["x"] = 4, ["name"] = "default:steelblock", ["z"] = 16, ["meta"] = { ["inventory"] = {  }, ["fields"] = {  } }, ["param2"] = 0, ["param1"] = 0 }, { ["y"] = 2, ["x"] = 4, ["name"] = "default:steelblock", ["z"] = 17, ["meta"] = { ["inventory"] = {  }, ["fields"] = {  } }, ["param2"] = 0, ["param1"] = 0 }, { ["y"] = 2, ["x"] = 4, ["name"] = "default:steelblock", ["z"] = 18, ["meta"] = { ["inventory"] = {  }, ["fields"] = {  } }, ["param2"] = 0, ["param1"] = 0 }, { ["y"] = 3, ["x"] = 4, ["name"] = "default:steelblock", ["z"] = 0, ["meta"] = { ["inventory"] = {  }, ["fields"] = {  } }, ["param2"] = 0, ["param1"] = 0 }, { ["y"] = 3, ["x"] = 4, ["name"] = "default:steelblock", ["z"] = 1, ["meta"] = { ["inventory"] = {  }, ["fields"] = {  } }, ["param2"] = 0, ["param1"] = 0 }, { ["y"] = 3, ["x"] = 4, ["name"] = "default:steelblock", ["z"] = 2, ["meta"] = { ["inventory"] = {  }, ["fields"] = {  } }, ["param2"] = 0, ["param1"] = 0 }, { ["y"] = 3, ["x"] = 4, ["name"] = "default:steelblock", ["z"] = 3, ["meta"] = { ["inventory"] = {  }, ["fields"] = {  } }, ["param2"] = 0, ["param1"] = 0 }, { ["y"] = 3, ["x"] = 4, ["name"] = "default:steelblock", ["z"] = 4, ["meta"] = { ["inventory"] = {  }, ["fields"] = {  } }, ["param2"] = 0, ["param1"] = 0 }, { ["y"] = 3, ["x"] = 4, ["name"] = "default:steelblock", ["z"] = 5, ["meta"] = { ["inventory"] = {  }, ["fields"] = {  } }, ["param2"] = 0, ["param1"] = 0 }, { ["y"] = 3, ["x"] = 4, ["name"] = "default:steelblock", ["z"] = 6, ["meta"] = { ["inventory"] = {  }, ["fields"] = {  } }, ["param2"] = 0, ["param1"] = 0 }, { ["y"] = 3, ["x"] = 4, ["name"] = "default:steelblock", ["z"] = 7, ["meta"] = { ["inventory"] = {  }, ["fields"] = {  } }, ["param2"] = 0, ["param1"] = 0 }, { ["y"] = 3, ["x"] = 4, ["name"] = "default:steelblock", ["z"] = 8, ["meta"] = { ["inventory"] = {  }, ["fields"] = {  } }, ["param2"] = 0, ["param1"] = 0 }, { ["y"] = 3, ["x"] = 4, ["name"] = "default:steelblock", ["z"] = 9, ["meta"] = { ["inventory"] = {  }, ["fields"] = {  } }, ["param2"] = 0, ["param1"] = 0 }, { ["y"] = 3, ["x"] = 4, ["name"] = "default:steelblock", ["z"] = 10, ["meta"] = { ["inventory"] = {  }, ["fields"] = {  } }, ["param2"] = 0, ["param1"] = 0 }, { ["y"] = 3, ["x"] = 4, ["name"] = "default:steelblock", ["z"] = 11, ["meta"] = { ["inventory"] = {  }, ["fields"] = {  } }, ["param2"] = 0, ["param1"] = 0 }, { ["y"] = 3, ["x"] = 4, ["name"] = "default:steelblock", ["z"] = 12, ["meta"] = { ["inventory"] = {  }, ["fields"] = {  } }, ["param2"] = 0, ["param1"] = 0 }, { ["y"] = 3, ["x"] = 4, ["name"] = "default:steelblock", ["z"] = 13, ["meta"] = { ["inventory"] = {  }, ["fields"] = {  } }, ["param2"] = 0, ["param1"] = 0 }, { ["y"] = 3, ["x"] = 4, ["name"] = "default:steelblock", ["z"] = 14, ["meta"] = { ["inventory"] = {  }, ["fields"] = {  } }, ["param2"] = 0, ["param1"] = 0 }, { ["y"] = 3, ["x"] = 4, ["name"] = "default:steelblock", ["z"] = 15, ["meta"] = { ["inventory"] = {  }, ["fields"] = {  } }, ["param2"] = 0, ["param1"] = 0 }, { ["y"] = 3, ["x"] = 4, ["name"] = "default:steelblock", ["z"] = 16, ["meta"] = { ["inventory"] = {  }, ["fields"] = {  } }, ["param2"] = 0, ["param1"] = 0 }, { ["y"] = 3, ["x"] = 4, ["name"] = "default:steelblock", ["z"] = 17, ["meta"] = { ["inventory"] = {  }, ["fields"] = {  } }, ["param2"] = 0, ["param1"] = 0 }, { ["y"] = 3, ["x"] = 4, ["name"] = "default:steelblock", ["z"] = 18, ["meta"] = { ["inventory"] = {  }, ["fields"] = {  } }, ["param2"] = 0, ["param1"] = 0 }, { ["y"] = 4, ["x"] = 4, ["name"] = "default:steelblock", ["z"] = 0, ["meta"] = { ["inventory"] = {  }, ["fields"] = {  } }, ["param2"] = 0, ["param1"] = 0 }, { ["y"] = 4, ["x"] = 4, ["name"] = "default:steelblock", ["z"] = 1, ["meta"] = { ["inventory"] = {  }, ["fields"] = {  } }, ["param2"] = 0, ["param1"] = 0 }, { ["y"] = 4, ["x"] = 4, ["name"] = "default:steelblock", ["z"] = 2, ["meta"] = { ["inventory"] = {  }, ["fields"] = {  } }, ["param2"] = 0, ["param1"] = 0 }, { ["y"] = 4, ["x"] = 4, ["name"] = "default:steelblock", ["z"] = 3, ["meta"] = { ["inventory"] = {  }, ["fields"] = {  } }, ["param2"] = 0, ["param1"] = 0 }, { ["y"] = 4, ["x"] = 4, ["name"] = "default:steelblock", ["z"] = 4, ["meta"] = { ["inventory"] = {  }, ["fields"] = {  } }, ["param2"] = 0, ["param1"] = 0 }, { ["y"] = 4, ["x"] = 4, ["name"] = "default:steelblock", ["z"] = 5, ["meta"] = { ["inventory"] = {  }, ["fields"] = {  } }, ["param2"] = 0, ["param1"] = 0 }, { ["y"] = 4, ["x"] = 4, ["name"] = "default:steelblock", ["z"] = 6, ["meta"] = { ["inventory"] = {  }, ["fields"] = {  } }, ["param2"] = 0, ["param1"] = 0 }, { ["y"] = 4, ["x"] = 4, ["name"] = "default:steelblock", ["z"] = 7, ["meta"] = { ["inventory"] = {  }, ["fields"] = {  } }, ["param2"] = 0, ["param1"] = 0 }, { ["y"] = 4, ["x"] = 4, ["name"] = "default:steelblock", ["z"] = 8, ["meta"] = { ["inventory"] = {  }, ["fields"] = {  } }, ["param2"] = 0, ["param1"] = 0 }, { ["y"] = 4, ["x"] = 4, ["name"] = "default:steelblock", ["z"] = 9, ["meta"] = { ["inventory"] = {  }, ["fields"] = {  } }, ["param2"] = 0, ["param1"] = 0 }, { ["y"] = 4, ["x"] = 4, ["name"] = "default:steelblock", ["z"] = 10, ["meta"] = { ["inventory"] = {  }, ["fields"] = {  } }, ["param2"] = 0, ["param1"] = 0 }, { ["y"] = 4, ["x"] = 4, ["name"] = "default:steelblock", ["z"] = 11, ["meta"] = { ["inventory"] = {  }, ["fields"] = {  } }, ["param2"] = 0, ["param1"] = 0 }, { ["y"] = 4, ["x"] = 4, ["name"] = "default:steelblock", ["z"] = 12, ["meta"] = { ["inventory"] = {  }, ["fields"] = {  } }, ["param2"] = 0, ["param1"] = 0 }, { ["y"] = 4, ["x"] = 4, ["name"] = "default:steelblock", ["z"] = 13, ["meta"] = { ["inventory"] = {  }, ["fields"] = {  } }, ["param2"] = 0, ["param1"] = 0 }, { ["y"] = 4, ["x"] = 4, ["name"] = "default:steelblock", ["z"] = 14, ["meta"] = { ["inventory"] = {  }, ["fields"] = {  } }, ["param2"] = 0, ["param1"] = 0 }, { ["y"] = 4, ["x"] = 4, ["name"] = "default:steelblock", ["z"] = 15, ["meta"] = { ["inventory"] = {  }, ["fields"] = {  } }, ["param2"] = 0, ["param1"] = 0 }, { ["y"] = 4, ["x"] = 4, ["name"] = "default:steelblock", ["z"] = 16, ["meta"] = { ["inventory"] = {  }, ["fields"] = {  } }, ["param2"] = 0, ["param1"] = 0 }, { ["y"] = 4, ["x"] = 4, ["name"] = "default:steelblock", ["z"] = 17, ["meta"] = { ["inventory"] = {  }, ["fields"] = {  } }, ["param2"] = 0, ["param1"] = 0 }, { ["y"] = 4, ["x"] = 4, ["name"] = "default:steelblock", ["z"] = 18, ["meta"] = { ["inventory"] = {  }, ["fields"] = {  } }, ["param2"] = 0, ["param1"] = 0 }, { ["y"] = 5, ["x"] = 4, ["name"] = "default:steelblock", ["z"] = 0, ["meta"] = { ["inventory"] = {  }, ["fields"] = {  } }, ["param2"] = 0, ["param1"] = 0 }, { ["y"] = 5, ["x"] = 4, ["name"] = "default:steelblock", ["z"] = 1, ["meta"] = { ["inventory"] = {  }, ["fields"] = {  } }, ["param2"] = 0, ["param1"] = 0 }, { ["y"] = 5, ["x"] = 4, ["name"] = "default:steelblock", ["z"] = 2, ["meta"] = { ["inventory"] = {  }, ["fields"] = {  } }, ["param2"] = 0, ["param1"] = 0 }, { ["y"] = 5, ["x"] = 4, ["name"] = "default:steelblock", ["z"] = 3, ["meta"] = { ["inventory"] = {  }, ["fields"] = {  } }, ["param2"] = 0, ["param1"] = 0 }, { ["y"] = 5, ["x"] = 4, ["name"] = "default:steelblock", ["z"] = 4, ["meta"] = { ["inventory"] = {  }, ["fields"] = {  } }, ["param2"] = 0, ["param1"] = 0 }, { ["y"] = 5, ["x"] = 4, ["name"] = "default:steelblock", ["z"] = 5, ["meta"] = { ["inventory"] = {  }, ["fields"] = {  } }, ["param2"] = 0, ["param1"] = 0 }, { ["y"] = 5, ["x"] = 4, ["name"] = "default:steelblock", ["z"] = 6, ["meta"] = { ["inventory"] = {  }, ["fields"] = {  } }, ["param2"] = 0, ["param1"] = 0 }, { ["y"] = 5, ["x"] = 4, ["name"] = "default:steelblock", ["z"] = 7, ["meta"] = { ["inventory"] = {  }, ["fields"] = {  } }, ["param2"] = 0, ["param1"] = 0 }, { ["y"] = 5, ["x"] = 4, ["name"] = "default:steelblock", ["z"] = 8, ["meta"] = { ["inventory"] = {  }, ["fields"] = {  } }, ["param2"] = 0, ["param1"] = 0 }, { ["y"] = 5, ["x"] = 4, ["name"] = "default:steelblock", ["z"] = 9, ["meta"] = { ["inventory"] = {  }, ["fields"] = {  } }, ["param2"] = 0, ["param1"] = 0 }, { ["y"] = 5, ["x"] = 4, ["name"] = "default:steelblock", ["z"] = 10, ["meta"] = { ["inventory"] = {  }, ["fields"] = {  } }, ["param2"] = 0, ["param1"] = 0 }, { ["y"] = 5, ["x"] = 4, ["name"] = "default:steelblock", ["z"] = 11, ["meta"] = { ["inventory"] = {  }, ["fields"] = {  } }, ["param2"] = 0, ["param1"] = 0 }, { ["y"] = 5, ["x"] = 4, ["name"] = "default:steelblock", ["z"] = 12, ["meta"] = { ["inventory"] = {  }, ["fields"] = {  } }, ["param2"] = 0, ["param1"] = 0 }, { ["y"] = 5, ["x"] = 4, ["name"] = "default:steelblock", ["z"] = 13, ["meta"] = { ["inventory"] = {  }, ["fields"] = {  } }, ["param2"] = 0, ["param1"] = 0 }, { ["y"] = 5, ["x"] = 4, ["name"] = "default:steelblock", ["z"] = 14, ["meta"] = { ["inventory"] = {  }, ["fields"] = {  } }, ["param2"] = 0, ["param1"] = 0 }, { ["y"] = 5, ["x"] = 4, ["name"] = "default:steelblock", ["z"] = 15, ["meta"] = { ["inventory"] = {  }, ["fields"] = {  } }, ["param2"] = 0, ["param1"] = 0 }, { ["y"] = 5, ["x"] = 4, ["name"] = "default:steelblock", ["z"] = 16, ["meta"] = { ["inventory"] = {  }, ["fields"] = {  } }, ["param2"] = 0, ["param1"] = 0 }, { ["y"] = 5, ["x"] = 4, ["name"] = "default:steelblock", ["z"] = 17, ["meta"] = { ["inventory"] = {  }, ["fields"] = {  } }, ["param2"] = 0, ["param1"] = 0 }, { ["y"] = 5, ["x"] = 4, ["name"] = "default:steelblock", ["z"] = 18, ["meta"] = { ["inventory"] = {  }, ["fields"] = {  } }, ["param2"] = 0, ["param1"] = 0 } }